Workbook

Sheet CONFIG
A1: Año | B1: 2026
A3: Cómo usar (año a año):
A4: 1) Cambia el año en B1. Todas las hojas de meses se actualizan automáticamente.
A5: 2) En la hoja LECTURAS, completa la tabla usando la clave MM-DD (ej: 01-15).
A6: - Así no tienes que rehacer nada cada año: la clave MM-DD es igual siempre.
A7: 3) Las lecturas se muestran automáticamente en cada día del mes.
A8: 4) El rango de búsqueda está configurado hasta la fila 1000 (puedes ampliarlo si lo necesitas).
A9: 5) Exporta a PDF si quieres imprimir.

Sheet LECTURAS
A1: MM-DD | B1: Lectura | C1: MM-DD
A2: =TRIM(C2) -> 01-01 | B2: Génesis 1–3; Juan 1–2 | C2: 01-01
A3: =TRIM(C3) -> 01-02 | B3: Génesis 4–5; Juan 3 | C3: 01-02
A4: =TRIM(C4) -> 01-03 | B4: Génesis 6–7; Juan 4 | C4: 01-03
A5: =TRIM(C5) -> 01-04 | B5: Génesis 8–9; Juan 5 | C5: 01-04
A6: =TRIM(C6) -> 01-05 | B6: Génesis 10–11; Juan 6 | C6: 01-05
A7: =TRIM(C7) -> 01-06 | B7: Génesis 12–13; Juan 7 | C7: 01-06
A8: =TRIM(C8) -> 01-07 | B8: Génesis 14–15; Juan 8 | C8: 01-07
A9: =TRIM(C9) -> 01-08 | B9: Génesis 16–18; Juan 9–10 | C9: 01-08
A10: =TRIM(C10) -> 01-09 | B10: Génesis 19–20; Juan 11 | C10: 01-09
A11: =TRIM(C11) -> 01-10 | B11: Génesis 21–22; Juan 12 | C11: 01-10
A12: =TRIM(C12) -> 01-11 | B12: Génesis 23–24; Juan 13 | C12: 01-11
A13: =TRIM(C13) -> 01-12 | B13: Génesis 25–26; Juan 14 | C13: 01-12
... A366: =TRIM(C366) -> 12-31 | B366: Apocalipsis 22 | C366: 12-31

Sheet Enero
B2: Enero | K2: 1
B3: Domingo | C3: Lunes | D3: Martes | E3: Miércoles | F3: Jueves | G3: Viernes | H3: Sábado | K3: =DATE(CONFIG!$B$1,$K$2,1) -> 46023
B4: =IF((($I4*7 + COLUMN()-COLUMN($B$4)+1) - $K$4 + 1)<1,"",IF((($I4*7 + COLUMN()-COLUMN($B$4)+1) - $K$4 + 1)>$K$5,"",(($I4*7 + COLUMN()-COLUMN($B$4)+1) - $K$4 + 1))) | C4: =IF((($I4*7 + COLUMN()-COLUMN($B$4)+1) - $K$4 + 1)<1,"",IF((($I4*7 + COLUMN()-COLUMN($B$4)+1) - $K$4 + 1)>$K$5,"",(($I4*7 + COLUMN()-COLUMN($B$4)+1) - $K$4 + 1))) | D4: =IF((($I4*7 + COLUMN()-COLUMN($B$4)+1) - $K$4 + 1)<1,"",IF((($I4*7 + COLUMN()-COLUMN($B$4)+1) - $K$4 + 1)>$K$5,"",(($I4*7 + COLUMN()-COLUMN($B$4)+1) - $K$4 + 1))) | E4: =IF((($I4*7 + COLUMN()-COLUMN($B$4)+1) - $K$4 + 1)<1,"",IF((($I4*7 + COLUMN()-COLUMN($B$4)+1) - $K$4 + 1)>$K$5,"",(($I4*7 + COLUMN()-COLUMN($B$4)+1) - $K$4 + 1))) | F4: =IF((($I4*7 + COLUMN()-COLUMN($B$4)+1) - $K$4 + 1)<1,"",IF((($I4*7 + COLUMN()-COLUMN($B$4)+1) - $K$4 + 1)>$K$5,"",(($I4*7 + COLUMN()-COLUMN($B$4)+1) - $K$4 + 1))) -> 1 | G4: =IF((($I4*7 + COLUMN()-COLUMN($B$4)+1) - $K$4 + 1)<1,"",IF((($I4*7 + COLUMN()-COLUMN($B$4)+1) - $K$4 + 1)>$K$5,"",(($I4*7 + COLUMN()-COLUMN($B$4)+1) - $K$4 + 1))) -> 2 | H4: =IF((($I4*7 + COLUMN()-COLUMN($B$4)+1) - $K$4 + 1)<1,"",IF((($I4*7 + COLUMN()-COLUMN($B$4)+1) - $K$4 + 1)>$K$5,"",(($I4*7 + COLUMN()-COLUMN($B$4)+1) - $K$4 + 1))) -> 3 | I4: 0 | K4: =WEEKDAY($K$3,1) -> 5
B5: =IF(B4="","",IFERROR(VLOOKUP(TEXT(DATE(CONFIG!$B$1,$K$2,B4),"mm-dd"),LECTURAS!$A$2:$B$1000,2,FALSE),"")) | C5: =IF(C4="","",IFERROR(VLOOKUP(TEXT(DATE(CONFIG!$B$1,$K$2,C4),"mm-dd"),LECTURAS!$A$2:$B$1000,2,FALSE),"")) | D5: =IF(D4="","",IFERROR(VLOOKUP(TEXT(DATE(CONFIG!$B$1,$K$2,D4),"mm-dd"),LECTURAS!$A$2:$B$1000,2,FALSE),"")) | E5: =IF(E4="","",IFERROR(VLOOKUP(TEXT(DATE(CONFIG!$B$1,$K$2,E4),"mm-dd"),LECTURAS!$A$2:$B$1000,2,FALSE),"")) | F5: =IF(F4="","",IFERROR(VLOOKUP(TEXT(DATE(CONFIG!$B$1,$K$2,F4),"mm-dd"),LECTURAS!$A$2:$B$1000,2,FALSE),"")) -> Génesis 1–3; Juan 1–2 | G5: =IF(G4="","",IFERROR(VLOOKUP(TEXT(DATE(CONFIG!$B$1,$K$2,G4),"mm-dd"),LECTURAS!$A$2:$B$1000,2,FALSE),"")) -> Génesis 4–5; Juan 3 | H5: =IF(H4="","",IFERROR(VLOOKUP(TEXT(DATE(CONFIG!$B$1,$K$2,H4),"mm-dd"),LECTURAS!$A$2:$B$1000,2,FALSE),"")) -> Génesis 6–7; Juan 4 | I5: 0 | K5: =DAY(EOMONTH($K$3,0)) -> 31
B6: =IF((($I6*7 + COLUMN()-COLUMN($B$6)+1) - $K$4 + 1)<1,"",IF((($I6*7 + COLUMN()-COLUMN($B$6)+1) - $K$4 + 1)>$K$5,"",(($I6*7 + COLUMN()-COLUMN($B$6)+1) - $K$4 + 1))) -> 4 | C6: =IF((($I6*7 + COLUMN()-COLUMN($B$6)+1) - $K$4 + 1)<1,"",IF((($I6*7 + COLUMN()-COLUMN($B$6)+1) - $K$4 + 1)>$K$5,"",(($I6*7 + COLUMN()-COLUMN($B$6)+1) - $K$4 + 1))) -> 5 | D6: =IF((($I6*7 + COLUMN()-COLUMN($B$6)+1) - $K$4 + 1)<1,"",IF((($I6*7 + COLUMN()-COLUMN($B$6)+1) - $K$4 + 1)>$K$5,"",(($I6*7 + COLUMN()-COLUMN($B$6)+1) - $K$4 + 1))) -> 6 | E6: =IF((($I6*7 + COLUMN()-COLUMN($B$6)+1) - $K$4 + 1)<1,"",IF((($I6*7 + COLUMN()-COLUMN($B$6)+1) - $K$4 + 1)>$K$5,"",(($I6*7 + COLUMN()-COLUMN($B$6)+1) - $K$4 + 1))) -> 7 | F6: =IF((($I6*7 + COLUMN()-COLUMN($B$6)+1) - $K$4 + 1)<1,"",IF((($I6*7 + COLUMN()-COLUMN($B$6)+1) - $K$4 + 1)>$K$5,"",(($I6*7 + COLUMN()-COLUMN($B$6)+1) - $K$4 + 1))) -> 8 | G6: =IF((($I6*7 + COLUMN()-COLUMN($B$6)+1) - $K$4 + 1)<1,"",IF((($I6*7 + COLUMN()-COLUMN($B$6)+1) - $K$4 + 1)>$K$5,"",(($I6*7 + COLUMN()-COLUMN($B$6)+1) - $K$4 + 1))) -> 9 | H6: =IF((($I6*7 + COLUMN()-COLUMN($B$6)+1) - $K$4 + 1)<1,"",IF((($I6*7 + COLUMN()-COLUMN($B$6)+1) - $K$4 + 1)>$K$5,"",(($I6*7 + COLUMN()-COLUMN($B$6)+1) - $K$4 + 1))) -> 10 | I6: 1
B7: =IF(B6="","",IFERROR(VLOOKUP(TEXT(DATE(CONFIG!$B$1,$K$2,B6),"mm-dd"),LECTURAS!$A$2:$B$1000,2,FALSE),"")) -> Génesis 8–9; Juan 5 | C7: =IF(C6="","",IFERROR(VLOOKUP(TEXT(DATE(CONFIG!$B$1,$K$2,C6),"mm-dd"),LECTURAS!$A$2:$B$1000,2,FALSE),"")) -> Génesis 10–11; Juan 6 | D7: =IF(D6="","",IFERROR(VLOOKUP(TEXT(DATE(CONFIG!$B$1,$K$2,D6),"mm-dd"),LECTURAS!$A$2:$B$1000,2,FALSE),"")) -> Génesis 12–13; Juan 7 | E7: =IF(E6="","",IFERROR(VLOOKUP(TEXT(DATE(CONFIG!$B$1,$K$2,E6),"mm-dd"),LECTURAS!$A$2:$B$1000,2,FALSE),"")) -> Génesis 14–15; Juan 8 | F7: =IF(F6="","",IFERROR(VLOOKUP(TEXT(DATE(CONFIG!$B$1,$K$2,F6),"mm-dd"),LECTURAS!$A$2:$B$1000,2,FALSE),"")) -> Génesis 16–18; Juan 9–10 | G7: =IF(G6="","",IFERROR(VLOOKUP(TEXT(DATE(CONFIG!$B$1,$K$2,G6),"mm-dd"),LECTURAS!$A$2:$B$1000,2,FALSE),"")) -> Génesis 19–20; Juan 11 | H7: =IF(H6="","",IFERROR(VLOOKUP(TEXT(DATE(CONFIG!$B$1,$K$2,H6),"mm-dd"),LECTURAS!$A$2:$B$1000,2,FALSE),"")) -> Génesis 21–22; Juan 12 | I7: 1
B8: =IF((($I8*7 + COLUMN()-COLUMN($B$8)+1) - $K$4 + 1)<1,"",IF((($I8*7 + COLUMN()-COLUMN($B$8)+1) - $K$4 + 1)>$K$5,"",(($I8*7 + COLUMN()-COLUMN($B$8)+1) - $K$4 + 1))) -> 11 | C8: =IF((($I8*7 + COLUMN()-COLUMN($B$8)+1) - $K$4 + 1)<1,"",IF((($I8*7 + COLUMN()-COLUMN($B$8)+1) - $K$4 + 1)>$K$5,"",(($I8*7 + COLUMN()-COLUMN($B$8)+1) - $K$4 + 1))) -> 12 | D8: =IF((($I8*7 + COLUMN()-COLUMN($B$8)+1) - $K$4 + 1)<1,"",IF((($I8*7 + COLUMN()-COLUMN($B$8)+1) - $K$4 + 1)>$K$5,"",(($I8*7 + COLUMN()-COLUMN($B$8)+1) - $K$4 + 1))) -> 13 | E8: =IF((($I8*7 + COLUMN()-COLUMN($B$8)+1) - $K$4 + 1)<1,"",IF((($I8*7 + COLUMN()-COLUMN($B$8)+1) - $K$4 + 1)>$K$5,"",(($I8*7 + COLUMN()-COLUMN($B$8)+1) - $K$4 + 1))) -> 14 | F8: =IF((($I8*7 + COLUMN()-COLUMN($B$8)+1) - $K$4 + 1)<1,"",IF((($I8*7 + COLUMN()-COLUMN($B$8)+1) - $K$4 + 1)>$K$5,"",(($I8*7 + COLUMN()-COLUMN($B$8)+1) - $K$4 + 1))) -> 15 | G8: =IF((($I8*7 + COLUMN()-COLUMN($B$8)+1) - $K$4 + 1)<1,"",IF((($I8*7 + COLUMN()-COLUMN($B$8)+1) - $K$4 + 1)>$K$5,"",(($I8*7 + COLUMN()-COLUMN($B$8)+1) - $K$4 + 1))) -> 16 | H8: =IF((($I8*7 + COLUMN()-COLUMN($B$8)+1) - $K$4 + 1)<1,"",IF((($I8*7 + COLUMN()-COLUMN($B$8)+1) - $K$4 + 1)>$K$5,"",(($I8*7 + COLUMN()-COLUMN($B$8)+1) - $K$4 + 1))) -> 17 | I8: 2
B9: =IF(B8="","",IFERROR(VLOOKUP(TEXT(DATE(CONFIG!$B$1,$K$2,B8),"mm-dd"),LECTURAS!$A$2:$B$1000,2,FALSE),"")) -> Génesis 23–24; Juan 13 | C9: =IF(C8="","",IFERROR(VLOOKUP(TEXT(DATE(CONFIG!$B$1,$K$2,C8),"mm-dd"),LECTURAS!$A$2:$B$1000,2,FALSE),"")) -> Génesis 25–26; Juan 14 | D9: =IF(D8="","",IFERROR(VLOOKUP(TEXT(DATE(CONFIG!$B$1,$K$2,D8),"mm-dd"),LECTURAS!$A$2:$B$1000,2,FALSE),"")) -> Génesis 27–28; Juan 15 | E9: =IF(E8="","",IFERROR(VLOOKUP(TEXT(DATE(CONFIG!$B$1,$K$2,E8),"mm-dd"),LECTURAS!$A$2:$B$1000,2,FALSE),"")) -> Génesis 29–30; Juan 16 | F9: =IF(F8="","",IFERROR(VLOOKUP(TEXT(DATE(CONFIG!$B$1,$K$2,F8),"mm-dd"),LECTURAS!$A$2:$B$1000,2,FALSE),"")) -> Génesis 31–34; Juan 17 | G9: =IF(G8="","",IFERROR(VLOOKUP(TEXT(DATE(CONFIG!$B$1,$K$2,G8),"mm-dd"),LECTURAS!$A$2:$B$1000,2,FALSE),"")) -> Génesis 35–36; Juan 18 | H9: =IF(H8="","",IFERROR(VLOOKUP(TEXT(DATE(CONFIG!$B$1,$K$2,H8),"mm-dd"),LECTURAS!$A$2:$B$1000,2,FALSE),"")) -> Génesis 37–38; Juan 19 | I9: 2
B10: =IF((($I10*7 + COLUMN()-COLUMN($B$10)+1) - $K$4 + 1)<1,"",IF((($I10*7 + COLUMN()-COLUMN($B$10)+1) - $K$4 + 1)>$K$5,"",(($I10*7 + COLUMN()-COLUMN($B$10)+1) - $K$4 + 1))) -> 18 | C10: =IF((($I10*7 + COLUMN()-COLUMN($B$10)+1) - $K$4 + 1)<1,"",IF((($I10*7 + COLUMN()-COLUMN($B$10)+1) - $K$4 + 1)>$K$5,"",(($I10*7 + COLUMN()-COLUMN($B$10)+1) - $K$4 + 1))) -> 19 | D10: =IF((($I10*7 + COLUMN()-COLUMN($B$10)+1) - $K$4 + 1)<1,"",IF((($I10*7 + COLUMN()-COLUMN($B$10)+1) - $K$4 + 1)>$K$5,"",(($I10*7 + COLUMN()-COLUMN($B$10)+1) - $K$4 + 1))) -> 20 | E10: =IF((($I10*7 + COLUMN()-COLUMN($B$10)+1) - $K$4 + 1)<1,"",IF((($I10*7 + COLUMN()-COLUMN($B$10)+1) - $K$4 + 1)>$K$5,"",(($I10*7 + COLUMN()-COLUMN($B$10)+1) - $K$4 + 1))) -> 21 | F10: =IF((($I10*7 + COLUMN()-COLUMN($B$10)+1) - $K$4 + 1)<1,"",IF((($I10*7 + COLUMN()-COLUMN($B$10)+1) - $K$4 + 1)>$K$5,"",(($I10*7 + COLUMN()-COLUMN($B$10)+1) - $K$4 + 1))) -> 22 | G10: =IF((($I10*7 + COLUMN()-COLUMN($B$10)+1) - $K$4 + 1)<1,"",IF((($I10*7 + COLUMN()-COLUMN($B$10)+1) - $K$4 + 1)>$K$5,"",(($I10*7 + COLUMN()-COLUMN($B$10)+1) - $K$4 + 1))) -> 23 | H10: =IF((($I10*7 + COLUMN()-COLUMN($B$10)+1) - $K$4 + 1)<1,"",IF((($I10*7 + COLUMN()-COLUMN($B$10)+1) - $K$4 + 1)>$K$5,"",(($I10*7 + COLUMN()-COLUMN($B$10)+1) - $K$4 + 1))) -> 24 | I10: 3
B11: =IF(B10="","",IFERROR(VLOOKUP(TEXT(DATE(CONFIG!$B$1,$K$2,B10),"mm-dd"),LECTURAS!$A$2:$B$1000,2,FALSE),"")) -> Génesis 39–40; Juan 20 | C11: =IF(C10="","",IFERROR(VLOOKUP(TEXT(DATE(CONFIG!$B$1,$K$2,C10),"mm-dd"),LECTURAS!$A$2:$B$1000,2,FALSE),"")) -> Génesis 41–42; Juan 21 | D11: =IF(D10="","",IFERROR(VLOOKUP(TEXT(DATE(CONFIG!$B$1,$K$2,D10),"mm-dd"),LECTURAS!$A$2:$B$1000,2,FALSE),"")) -> Génesis 43–45 | E11: =IF(E10="","",IFERROR(VLOOKUP(TEXT(DATE(CONFIG!$B$1,$K$2,E10),"mm-dd"),LECTURAS!$A$2:$B$1000,2,FALSE),"")) -> Génesis 46–48 | F11: =IF(F10="","",IFERROR(VLOOKUP(TEXT(DATE(CONFIG!$B$1,$K$2,F10),"mm-dd"),LECTURAS!$A$2:$B$1000,2,FALSE),"")) -> Génesis 49–50; Éxodo 1–3 | G11: =IF(G10="","",IFERROR(VLOOKUP(TEXT(DATE(CONFIG!$B$1,$K$2,G10),"mm-dd"),LECTURAS!$A$2:$B$1000,2,FALSE),"")) -> Éxodo 4–5; Romanos 1 | H11: =IF(H10="","",IFERROR(VLOOKUP(TEXT(DATE(CONFIG!$B$1,$K$2,H10),"mm-dd"),LECTURAS!$A$2:$B$1000,2,FALSE),"")) -> Éxodo 6–7; Romanos 2 | I11: 3
B12: =IF((($I12*7 + COLUMN()-COLUMN($B$12)+1) - $K$4 + 1)<1,"",IF((($I12*7 + COLUMN()-COLUMN($B$12)+1) - $K$4 + 1)>$K$5,"",(($I12*7 + COLUMN()-COLUMN($B$12)+1) - $K$4 + 1))) -> 25 | C12: =IF((($I12*7 + COLUMN()-COLUMN($B$12)+1) - $K$4 + 1)<1,"",IF((($I12*7 + COLUMN()-COLUMN($B$12)+1) - $K$4 + 1)>$K$5,"",(($I12*7 + COLUMN()-COLUMN($B$12)+1) - $K$4 + 1))) -> 26 | D12: =IF((($I12*7 + COLUMN()-COLUMN($B$12)+1) - $K$4 + 1)<1,"",IF((($I12*7 + COLUMN()-COLUMN($B$12)+1) - $K$4 + 1)>$K$5,"",(($I12*7 + COLUMN()-COLUMN($B$12)+1) - $K$4 + 1))) -> 27 | E12: =IF((($I12*7 + COLUMN()-COLUMN($B$12)+1) - $K$4 + 1)<1,"",IF((($I12*7 + COLUMN()-COLUMN($B$12)+1) - $K$4 + 1)>$K$5,"",(($I12*7 + COLUMN()-COLUMN($B$12)+1) - $K$4 + 1))) -> 28 | F12: =IF((($I12*7 + COLUMN()-COLUMN($B$12)+1) - $K$4 + 1)<1,"",IF((($I12*7 + COLUMN()-COLUMN($B$12)+1) - $K$4 + 1)>$K$5,"",(($I12*7 + COLUMN()-COLUMN($B$12)+1) - $K$4 + 1))) -> 29 | G12: =IF((($I12*7 + COLUMN()-COLUMN($B$12)+1) - $K$4 + 1)<1,"",IF((($I12*7 + COLUMN()-COLUMN($B$12)+1) - $K$4 + 1)>$K$5,"",(($I12*7 + COLUMN()-COLUMN($B$12)+1) - $K$4 + 1))) -> 30 | H12: =IF((($I12*7 + COLUMN()-COLUMN($B$12)+1) - $K$4 + 1)<1,"",IF((($I12*7 + COLUMN()-COLUMN($B$12)+1) - $K$4 + 1)>$K$5,"",(($I12*7 + COLUMN()-COLUMN($B$12)+1) - $K$4 + 1))) -> 31 | I12: 4
B13: =IF(B12="","",IFERROR(VLOOKUP(TEXT(DATE(CONFIG!$B$1,$K$2,B12),"mm-dd"),LECTURAS!$A$2:$B$1000,2,FALSE),"")) -> Éxodo 8–9; Romanos 3 | C13: =IF(C12="","",IFERROR(VLOOKUP(TEXT(DATE(CONFIG!$B$1,$K$2,C12),"mm-dd"),LECTURAS!$A$2:$B$1000,2,FALSE),"")) -> Éxodo 10–11; Romanos 4 | D13: =IF(D12="","",IFERROR(VLOOKUP(TEXT(DATE(CONFIG!$B$1,$K$2,D12),"mm-dd"),LECTURAS!$A$2:$B$1000,2,FALSE),"")) -> Éxodo 12–13; Romanos 5 | E13: =IF(E12="","",IFERROR(VLOOKUP(TEXT(DATE(CONFIG!$B$1,$K$2,E12),"mm-dd"),LECTURAS!$A$2:$B$1000,2,FALSE),"")) -> Éxodo 14–15; Romanos 6 | F13: =IF(F12="","",IFERROR(VLOOKUP(TEXT(DATE(CONFIG!$B$1,$K$2,F12),"mm-dd"),LECTURAS!$A$2:$B$1000,2,FALSE),"")) -> Éxodo 16–20 | G13: =IF(G12="","",IFERROR(VLOOKUP(TEXT(DATE(CONFIG!$B$1,$K$2,G12),"mm-dd"),LECTURAS!$A$2:$B$1000,2,FALSE),"")) -> Éxodo 21–22; Romanos 7 | H13: =IF(H12="","",IFERROR(VLOOKUP(TEXT(DATE(CONFIG!$B$1,$K$2,H12),"mm-dd"),LECTURAS!$A$2:$B$1000,2,FALSE),"")) -> Éxodo 23–24; Romanos 8 | I13: 4
B14: =IF((($I14*7 + COLUMN()-COLUMN($B$14)+1) - $K$4 + 1)<1,"",IF((($I14*7 + COLUMN()-COLUMN($B$14)+1) - $K$4 + 1)>$K$5,"",(($I14*7 + COLUMN()-COLUMN($B$14)+1) - $K$4 + 1))) | C14: =IF((($I14*7 + COLUMN()-COLUMN($B$14)+1) - $K$4 + 1)<1,"",IF((($I14*7 + COLUMN()-COLUMN($B$14)+1) - $K$4 + 1)>$K$5,"",(($I14*7 + COLUMN()-COLUMN($B$14)+1) - $K$4 + 1))) | D14: =IF((($I14*7 + COLUMN()-COLUMN($B$14)+1) - $K$4 + 1)<1,"",IF((($I14*7 + COLUMN()-COLUMN($B$14)+1) - $K$4 + 1)>$K$5,"",(($I14*7 + COLUMN()-COLUMN($B$14)+1) - $K$4 + 1))) | E14: =IF((($I14*7 + COLUMN()-COLUMN($B$14)+1) - $K$4 + 1)<1,"",IF((($I14*7 + COLUMN()-COLUMN($B$14)+1) - $K$4 + 1)>$K$5,"",(($I14*7 + COLUMN()-COLUMN($B$14)+1) - $K$4 + 1))) | F14: =IF((($I14*7 + COLUMN()-COLUMN($B$14)+1) - $K$4 + 1)<1,"",IF((($I14*7 + COLUMN()-COLUMN($B$14)+1) - $K$4 + 1)>$K$5,"",(($I14*7 + COLUMN()-COLUMN($B$14)+1) - $K$4 + 1))) | G14: =IF((($I14*7 + COLUMN()-COLUMN($B$14)+1) - $K$4 + 1)<1,"",IF((($I14*7 + COLUMN()-COLUMN($B$14)+1) - $K$4 + 1)>$K$5,"",(($I14*7 + COLUMN()-COLUMN($B$14)+1) - $K$4 + 1))) | H14: =IF((($I14*7 + COLUMN()-COLUMN($B$14)+1) - $K$4 + 1)<1,"",IF((($I14*7 + COLUMN()-COLUMN($B$14)+1) - $K$4 + 1)>$K$5,"",(($I14*7 + COLUMN()-COLUMN($B$14)+1) - $K$4 + 1))) | I14: 5
B15: =IF(B14="","",IFERROR(VLOOKUP(TEXT(DATE(CONFIG!$B$1,$K$2,B14),"mm-dd"),LECTURAS!$A$2:$B$1000,2,FALSE),"")) | C15: =IF(C14="","",IFERROR(VLOOKUP(TEXT(DATE(CONFIG!$B$1,$K$2,C14),"mm-dd"),LECTURAS!$A$2:$B$1000,2,FALSE),"")) | D15: =IF(D14="","",IFERROR(VLOOKUP(TEXT(DATE(CONFIG!$B$1,$K$2,D14),"mm-dd"),LECTURAS!$A$2:$B$1000,2,FALSE),"")) | E15: =IF(E14="","",IFERROR(VLOOKUP(TEXT(DATE(CONFIG!$B$1,$K$2,E14),"mm-dd"),LECTURAS!$A$2:$B$1000,2,FALSE),"")) | F15: =IF(F14="","",IFERROR(VLOOKUP(TEXT(DATE(CONFIG!$B$1,$K$2,F14),"mm-dd"),LECTURAS!$A$2:$B$1000,2,FALSE),"")) | G15: =IF(G14="","",IFERROR(VLOOKUP(TEXT(DATE(CONFIG!$B$1,$K$2,G14),"mm-dd"),LECTURAS!$A$2:$B$1000,2,FALSE),"")) | H15: =IF(H14="","",IFERROR(VLOOKUP(TEXT(DATE(CONFIG!$B$1,$K$2,H14),"mm-dd"),LECTURAS!$A$2:$B$1000,2,FALSE),"")) | I15: 5

Sheet Febrero
B2: Febrero | K2: 2
B3: Domingo | C3: Lunes | D3: Martes | E3: Miércoles | F3: Jueves | G3: Viernes | H3: Sábado | K3: =DATE(CONFIG!$B$1,$K$2,1) -> 46054
B4: =IF((($I4*7 + COLUMN()-COLUMN($B$4)+1) - $K$4 + 1)<1,"",IF((($I4*7 + COLUMN()-COLUMN($B$4)+1) - $K$4 + 1)>$K$5,"",(($I4*7 + COLUMN()-COLUMN($B$4)+1) - $K$4 + 1))) -> 1 | C4: =IF((($I4*7 + COLUMN()-COLUMN($B$4)+1) - $K$4 + 1)<1,"",IF((($I4*7 + COLUMN()-COLUMN($B$4)+1) - $K$4 + 1)>$K$5,"",(($I4*7 + COLUMN()-COLUMN($B$4)+1) - $K$4 + 1))) -> 2 | D4: =IF((($I4*7 + COLUMN()-COLUMN($B$4)+1) - $K$4 + 1)<1,"",IF((($I4*7 + COLUMN()-COLUMN($B$4)+1) - $K$4 + 1)>$K$5,"",(($I4*7 + COLUMN()-COLUMN($B$4)+1) - $K$4 + 1))) -> 3 | E4: =IF((($I4*7 + COLUMN()-COLUMN($B$4)+1) - $K$4 + 1)<1,"",IF((($I4*7 + COLUMN()-COLUMN($B$4)+1) - $K$4 + 1)>$K$5,"",(($I4*7 + COLUMN()-COLUMN($B$4)+1) - $K$4 + 1))) -> 4 | F4: =IF((($I4*7 + COLUMN()-COLUMN($B$4)+1) - $K$4 + 1)<1,"",IF((($I4*7 + COLUMN()-COLUMN($B$4)+1) - $K$4 + 1)>$K$5,"",(($I4*7 + COLUMN()-COLUMN($B$4)+1) - $K$4 + 1))) -> 5 | G4: =IF((($I4*7 + COLUMN()-COLUMN($B$4)+1) - $K$4 + 1)<1,"",IF((($I4*7 + COLUMN()-COLUMN($B$4)+1) - $K$4 + 1)>$K$5,"",(($I4*7 + COLUMN()-COLUMN($B$4)+1) - $K$4 + 1))) -> 6 | H4: =IF((($I4*7 + COLUMN()-COLUMN($B$4)+1) - $K$4 + 1)<1,"",IF((($I4*7 + COLUMN()-COLUMN($B$4)+1) - $K$4 + 1)>$K$5,"",(($I4*7 + COLUMN()-COLUMN($B$4)+1) - $K$4 + 1))) -> 7 | I4: 0 | K4: =WEEKDAY($K$3,1) -> 1
B5: =IF(B4="","",IFERROR(VLOOKUP(TEXT(DATE(CONFIG!$B$1,$K$2,B4),"mm-dd"),LECTURAS!$A$2:$B$1000,2,FALSE),"")) -> Éxodo 25–26; Romanos 9 | C5: =IF(C4="","",IFERROR(VLOOKUP(TEXT(DATE(CONFIG!$B$1,$K$2,C4),"mm-dd"),LECTURAS!$A$2:$B$1000,2,FALSE),"")) -> Éxodo 27–28; Romanos 10 | D5: =IF(D4="","",IFERROR(VLOOKUP(TEXT(DATE(CONFIG!$B$1,$K$2,D4),"mm-dd"),LECTURAS!$A$2:$B$1000,2,FALSE),"")) -> Éxodo 29–30; Romanos 11 | E5: =IF(E4="","",IFERROR(VLOOKUP(TEXT(DATE(CONFIG!$B$1,$K$2,E4),"mm-dd"),LECTURAS!$A$2:$B$1000,2,FALSE),"")) -> Éxodo 31–32; Romanos 12 | F5: =IF(F4="","",IFERROR(VLOOKUP(TEXT(DATE(CONFIG!$B$1,$K$2,F4),"mm-dd"),LECTURAS!$A$2:$B$1000,2,FALSE),"")) -> Éxodo 33–36; Romanos 13 | G5: =IF(G4="","",IFERROR(VLOOKUP(TEXT(DATE(CONFIG!$B$1,$K$2,G4),"mm-dd"),LECTURAS!$A$2:$B$1000,2,FALSE),"")) -> Éxodo 37–38; Romanos 14 | H5: =IF(H4="","",IFERROR(VLOOKUP(TEXT(DATE(CONFIG!$B$1,$K$2,H4),"mm-dd"),LECTURAS!$A$2:$B$1000,2,FALSE),"")) -> Éxodo 39–40; Romanos 15 | I5: 0 | K5: =DAY(EOMONTH($K$3,0)) -> 28
B6: =IF((($I6*7 + COLUMN()-COLUMN($B$6)+1) - $K$4 + 1)<1,"",IF((($I6*7 + COLUMN()-COLUMN($B$6)+1) - $K$4 + 1)>$K$5,"",(($I6*7 + COLUMN()-COLUMN($B$6)+1) - $K$4 + 1))) -> 8 | C6: =IF((($I6*7 + COLUMN()-COLUMN($B$6)+1) - $K$4 + 1)<1,"",IF((($I6*7 + COLUMN()-COLUMN($B$6)+1) - $K$4 + 1)>$K$5,"",(($I6*7 + COLUMN()-COLUMN($B$6)+1) - $K$4 + 1))) -> 9 | D6: =IF((($I6*7 + COLUMN()-COLUMN($B$6)+1) - $K$4 + 1)<1,"",IF((($I6*7 + COLUMN()-COLUMN($B$6)+1) - $K$4 + 1)>$K$5,"",(($I6*7 + COLUMN()-COLUMN($B$6)+1) - $K$4 + 1))) -> 10 | E6: =IF((($I6*7 + COLUMN()-COLUMN($B$6)+1) - $K$4 + 1)<1,"",IF((($I6*7 + COLUMN()-COLUMN($B$6)+1) - $K$4 + 1)>$K$5,"",(($I6*7 + COLUMN()-COLUMN($B$6)+1) - $K$4 + 1))) -> 11 | F6: =IF((($I6*7 + COLUMN()-COLUMN($B$6)+1) - $K$4 + 1)<1,"",IF((($I6*7 + COLUMN()-COLUMN($B$6)+1) - $K$4 + 1)>$K$5,"",(($I6*7 + COLUMN()-COLUMN($B$6)+1) - $K$4 + 1))) -> 12 | G6: =IF((($I6*7 + COLUMN()-COLUMN($B$6)+1) - $K$4 + 1)<1,"",IF((($I6*7 + COLUMN()-COLUMN($B$6)+1) - $K$4 + 1)>$K$5,"",(($I6*7 + COLUMN()-COLUMN($B$6)+1) - $K$4 + 1))) -> 13 | H6: =IF((($I6*7 + COLUMN()-COLUMN($B$6)+1) - $K$4 + 1)<1,"",IF((($I6*7 + COLUMN()-COLUMN($B$6)+1) - $K$4 + 1)>$K$5,"",(($I6*7 + COLUMN()-COLUMN($B$6)+1) - $K$4 + 1))) -> 14 | I6: 1
B7: =IF(B6="","",IFERROR(VLOOKUP(TEXT(DATE(CONFIG!$B$1,$K$2,B6),"mm-dd"),LECTURAS!$A$2:$B$1000,2,FALSE),"")) -> Levítico 1–2; Romanos 16 | C7: =IF(C6="","",IFERROR(VLOOKUP(TEXT(DATE(CONFIG!$B$1,$K$2,C6),"mm-dd"),LECTURAS!$A$2:$B$1000,2,FALSE),"")) -> Levítico 3–4; Hebreos 1 | D7: =IF(D6="","",IFERROR(VLOOKUP(TEXT(DATE(CONFIG!$B$1,$K$2,D6),"mm-dd"),LECTURAS!$A$2:$B$1000,2,FALSE),"")) -> Levítico 5–6; Hebreos 2 | E7: =IF(E6="","",IFERROR(VLOOKUP(TEXT(DATE(CONFIG!$B$1,$K$2,E6),"mm-dd"),LECTURAS!$A$2:$B$1000,2,FALSE),"")) -> Levítico 7–8; Hebreos 3 | F7: =IF(F6="","",IFERROR(VLOOKUP(TEXT(DATE(CONFIG!$B$1,$K$2,F6),"mm-dd"),LECTURAS!$A$2:$B$1000,2,FALSE),"")) -> Levítico 9–12; Hebreos 4 | G7: =IF(G6="","",IFERROR(VLOOKUP(TEXT(DATE(CONFIG!$B$1,$K$2,G6),"mm-dd"),LECTURAS!$A$2:$B$1000,2,FALSE),"")) -> Levítico 13–14; Hebreos 5 | H7: =IF(H6="","",IFERROR(VLOOKUP(TEXT(DATE(CONFIG!$B$1,$K$2,H6),"mm-dd"),LECTURAS!$A$2:$B$1000,2,FALSE),"")) -> Levítico 15–16; Hebreos 6 | I7: 1
B8: =IF((($I8*7 + COLUMN()-COLUMN($B$8)+1) - $K$4 + 1)<1,"",IF((($I8*7 + COLUMN()-COLUMN($B$8)+1) - $K$4 + 1)>$K$5,"",(($I8*7 + COLUMN()-COLUMN($B$8)+1) - $K$4 + 1))) -> 15 | C8: =IF((($I8*7 + COLUMN()-COLUMN($B$8)+1) - $K$4 + 1)<1,"",IF((($I8*7 + COLUMN()-COLUMN($B$8)+1) - $K$4 + 1)>$K$5,"",(($I8*7 + COLUMN()-COLUMN($B$8)+1) - $K$4 + 1))) -> 16 | D8: =IF((($I8*7 + COLUMN()-COLUMN($B$8)+1) - $K$4 + 1)<1,"",IF((($I8*7 + COLUMN()-COLUMN($B$8)+1) - $K$4 + 1)>$K$5,"",(($I8*7 + COLUMN()-COLUMN($B$8)+1) - $K$4 + 1))) -> 17 | E8: =IF((($I8*7 + COLUMN()-COLUMN($B$8)+1) - $K$4 + 1)<1,"",IF((($I8*7 + COLUMN()-COLUMN($B$8)+1) - $K$4 + 1)>$K$5,"",(($I8*7 + COLUMN()-COLUMN($B$8)+1) - $K$4 + 1))) -> 18 | F8: =IF((($I8*7 + COLUMN()-COLUMN($B$8)+1) - $K$4 + 1)<1,"",IF((($I8*7 + COLUMN()-COLUMN($B$8)+1) - $K$4 + 1)>$K$5,"",(($I8*7 + COLUMN()-COLUMN($B$8)+1) - $K$4 + 1))) -> 19 | G8: =IF((($I8*7 + COLUMN()-COLUMN($B$8)+1) - $K$4 + 1)<1,"",IF((($I8*7 + COLUMN()-COLUMN($B$8)+1) - $K$4 + 1)>$K$5,"",(($I8*7 + COLUMN()-COLUMN($B$8)+1) - $K$4 + 1))) -> 20 | H8: =IF((($I8*7 + COLUMN()-COLUMN($B$8)+1) - $K$4 + 1)<1,"",IF((($I8*7 + COLUMN()-COLUMN($B$8)+1) - $K$4 + 1)>$K$5,"",(($I8*7 + COLUMN()-COLUMN($B$8)+1) - $K$4 + 1))) -> 21 | I8: 2
B9: =IF(B8="","",IFERROR(VLOOKUP(TEXT(DATE(CONFIG!$B$1,$K$2,B8),"mm-dd"),LECTURAS!$A$2:$B$1000,2,FALSE),"")) -> Levítico 17–18; Hebreos 7 | C9: =IF(C8="","",IFERROR(VLOOKUP(TEXT(DATE(CONFIG!$B$1,$K$2,C8),"mm-dd"),LECTURAS!$A$2:$B$1000,2,FALSE),"")) -> Levítico 19–20; Hebreos 8 | D9: =IF(D8="","",IFERROR(VLOOKUP(TEXT(DATE(CONFIG!$B$1,$K$2,D8),"mm-dd"),LECTURAS!$A$2:$B$1000,2,FALSE),"")) -> Levítico 21–23; Hebreos 9 | E9: =IF(E8="","",IFERROR(VLOOKUP(TEXT(DATE(CONFIG!$B$1,$K$2,E8),"mm-dd"),LECTURAS!$A$2:$B$1000,2,FALSE),"")) -> Levítico 24–25; Hebreos 10–11 | F9: =IF(F8="","",IFERROR(VLOOKUP(TEXT(DATE(CONFIG!$B$1,$K$2,F8),"mm-dd"),LECTURAS!$A$2:$B$1000,2,FALSE),"")) -> Levítico 26–27; Hebreos 12–13 | G9: =IF(G8="","",IFERROR(VLOOKUP(TEXT(DATE(CONFIG!$B$1,$K$2,G8),"mm-dd"),LECTURAS!$A$2:$B$1000,2,FALSE),"")) -> Números 1–2; Hechos 1 | H9: =IF(H8="","",IFERROR(VLOOKUP(TEXT(DATE(CONFIG!$B$1,$K$2,H8),"mm-dd"),LECTURAS!$A$2:$B$1000,2,FALSE),"")) -> Números 3–4; Hechos 2 | I9: 2
B10: =IF((($I10*7 + COLUMN()-COLUMN($B$10)+1) - $K$4 + 1)<1,"",IF((($I10*7 + COLUMN()-COLUMN($B$10)+1) - $K$4 + 1)>$K$5,"",(($I10*7 + COLUMN()-COLUMN($B$10)+1) - $K$4 + 1))) -> 22 | C10: =IF((($I10*7 + COLUMN()-COLUMN($B$10)+1) - $K$4 + 1)<1,"",IF((($I10*7 + COLUMN()-COLUMN($B$10)+1) - $K$4 + 1)>$K$5,"",(($I10*7 + COLUMN()-COLUMN($B$10)+1) - $K$4 + 1))) -> 23 | D10: =IF((($I10*7 + COLUMN()-COLUMN($B$10)+1) - $K$4 + 1)<1,"",IF((($I10*7 + COLUMN()-COLUMN($B$10)+1) - $K$4 + 1)>$K$5,"",(($I10*7 + COLUMN()-COLUMN($B$10)+1) - $K$4 + 1))) -> 24 | E10: =IF((($I10*7 + COLUMN()-COLUMN($B$10)+1) - $K$4 + 1)<1,"",IF((($I10*7 + COLUMN()-COLUMN($B$10)+1) - $K$4 + 1)>$K$5,"",(($I10*7 + COLUMN()-COLUMN($B$10)+1) - $K$4 + 1))) -> 25 | F10: =IF((($I10*7 + COLUMN()-COLUMN($B$10)+1) - $K$4 + 1)<1,"",IF((($I10*7 + COLUMN()-COLUMN($B$10)+1) - $K$4 + 1)>$K$5,"",(($I10*7 + COLUMN()-COLUMN($B$10)+1) - $K$4 + 1))) -> 26 | G10: =IF((($I10*7 + COLUMN()-COLUMN($B$10)+1) - $K$4 + 1)<1,"",IF((($I10*7 + COLUMN()-COLUMN($B$10)+1) - $K$4 + 1)>$K$5,"",(($I10*7 + COLUMN()-COLUMN($B$10)+1) - $K$4 + 1))) -> 27 | H10: =IF((($I10*7 + COLUMN()-COLUMN($B$10)+1) - $K$4 + 1)<1,"",IF((($I10*7 + COLUMN()-COLUMN($B$10)+1) - $K$4 + 1)>$K$5,"",(($I10*7 + COLUMN()-COLUMN($B$10)+1) - $K$4 + 1))) -> 28 | I10: 3
B11: =IF(B10="","",IFERROR(VLOOKUP(TEXT(DATE(CONFIG!$B$1,$K$2,B10),"mm-dd"),LECTURAS!$A$2:$B$1000,2,FALSE),"")) -> Números 5–6; Hechos 3 | C11: =IF(C10="","",IFERROR(VLOOKUP(TEXT(DATE(CONFIG!$B$1,$K$2,C10),"mm-dd"),LECTURAS!$A$2:$B$1000,2,FALSE),"")) -> Números 7–8; Hechos 4 | D11: =IF(D10="","",IFERROR(VLOOKUP(TEXT(DATE(CONFIG!$B$1,$K$2,D10),"mm-dd"),LECTURAS!$A$2:$B$1000,2,FALSE),"")) -> Números 9–10; Hechos 5 | E11: =IF(E10="","",IFERROR(VLOOKUP(TEXT(DATE(CONFIG!$B$1,$K$2,E10),"mm-dd"),LECTURAS!$A$2:$B$1000,2,FALSE),"")) -> Números 11–12; Hechos 6–7 | F11: =IF(F10="","",IFERROR(VLOOKUP(TEXT(DATE(CONFIG!$B$1,$K$2,F10),"mm-dd"),LECTURAS!$A$2:$B$1000,2,FALSE),"")) -> Números 13–14; Hechos 8–9 | G11: =IF(G10="","",IFERROR(VLOOKUP(TEXT(DATE(CONFIG!$B$1,$K$2,G10),"mm-dd"),LECTURAS!$A$2:$B$1000,2,FALSE),"")) -> Números 15–16; Hechos 10 | H11: =IF(H10="","",IFERROR(VLOOKUP(TEXT(DATE(CONFIG!$B$1,$K$2,H10),"mm-dd"),LECTURAS!$A$2:$B$1000,2,FALSE),"")) -> Números 17–18; Hechos 11 | I11: 3
B12: =IF((($I12*7 + COLUMN()-COLUMN($B$12)+1) - $K$4 + 1)<1,"",IF((($I12*7 + COLUMN()-COLUMN($B$12)+1) - $K$4 + 1)>$K$5,"",(($I12*7 + COLUMN()-COLUMN($B$12)+1) - $K$4 + 1))) | C12: =IF((($I12*7 + COLUMN()-COLUMN($B$12)+1) - $K$4 + 1)<1,"",IF((($I12*7 + COLUMN()-COLUMN($B$12)+1) - $K$4 + 1)>$K$5,"",(($I12*7 + COLUMN()-COLUMN($B$12)+1) - $K$4 + 1))) | D12: =IF((($I12*7 + COLUMN()-COLUMN($B$12)+1) - $K$4 + 1)<1,"",IF((($I12*7 + COLUMN()-COLUMN($B$12)+1) - $K$4 + 1)>$K$5,"",(($I12*7 + COLUMN()-COLUMN($B$12)+1) - $K$4 + 1))) | E12: =IF((($I12*7 + COLUMN()-COLUMN($B$12)+1) - $K$4 + 1)<1,"",IF((($I12*7 + COLUMN()-COLUMN($B$12)+1) - $K$4 + 1)>$K$5,"",(($I12*7 + COLUMN()-COLUMN($B$12)+1) - $K$4 + 1))) | F12: =IF((($I12*7 + COLUMN()-COLUMN($B$12)+1) - $K$4 + 1)<1,"",IF((($I12*7 + COLUMN()-COLUMN($B$12)+1) - $K$4 + 1)>$K$5,"",(($I12*7 + COLUMN()-COLUMN($B$12)+1) - $K$4 + 1))) | G12: =IF((($I12*7 + COLUMN()-COLUMN($B$12)+1) - $K$4 + 1)<1,"",IF((($I12*7 + COLUMN()-COLUMN($B$12)+1) - $K$4 + 1)>$K$5,"",(($I12*7 + COLUMN()-COLUMN($B$12)+1) - $K$4 + 1))) | H12: =IF((($I12*7 + COLUMN()-COLUMN($B$12)+1) - $K$4 + 1)<1,"",IF((($I12*7 + COLUMN()-COLUMN($B$12)+1) - $K$4 + 1)>$K$5,"",(($I12*7 + COLUMN()-COLUMN($B$12)+1) - $K$4 + 1))) | I12: 4
B13: =IF(B12="","",IFERROR(VLOOKUP(TEXT(DATE(CONFIG!$B$1,$K$2,B12),"mm-dd"),LECTURAS!$A$2:$B$1000,2,FALSE),"")) | C13: =IF(C12="","",IFERROR(VLOOKUP(TEXT(DATE(CONFIG!$B$1,$K$2,C12),"mm-dd"),LECTURAS!$A$2:$B$1000,2,FALSE),"")) | D13: =IF(D12="","",IFERROR(VLOOKUP(TEXT(DATE(CONFIG!$B$1,$K$2,D12),"mm-dd"),LECTURAS!$A$2:$B$1000,2,FALSE),"")) | E13: =IF(E12="","",IFERROR(VLOOKUP(TEXT(DATE(CONFIG!$B$1,$K$2,E12),"mm-dd"),LECTURAS!$A$2:$B$1000,2,FALSE),"")) | F13: =IF(F12="","",IFERROR(VLOOKUP(TEXT(DATE(CONFIG!$B$1,$K$2,F12),"mm-dd"),LECTURAS!$A$2:$B$1000,2,FALSE),"")) | G13: =IF(G12="","",IFERROR(VLOOKUP(TEXT(DATE(CONFIG!$B$1,$K$2,G12),"mm-dd"),LECTURAS!$A$2:$B$1000,2,FALSE),"")) | H13: =IF(H12="","",IFERROR(VLOOKUP(TEXT(DATE(CONFIG!$B$1,$K$2,H12),"mm-dd"),LECTURAS!$A$2:$B$1000,2,FALSE),"")) | I13: 4
B14: =IF((($I14*7 + COLUMN()-COLUMN($B$14)+1) - $K$4 + 1)<1,"",IF((($I14*7 + COLUMN()-COLUMN($B$14)+1) - $K$4 + 1)>$K$5,"",(($I14*7 + COLUMN()-COLUMN($B$14)+1) - $K$4 + 1))) | C14: =IF((($I14*7 + COLUMN()-COLUMN($B$14)+1) - $K$4 + 1)<1,"",IF((($I14*7 + COLUMN()-COLUMN($B$14)+1) - $K$4 + 1)>$K$5,"",(($I14*7 + COLUMN()-COLUMN($B$14)+1) - $K$4 + 1))) | D14: =IF((($I14*7 + COLUMN()-COLUMN($B$14)+1) - $K$4 + 1)<1,"",IF((($I14*7 + COLUMN()-COLUMN($B$14)+1) - $K$4 + 1)>$K$5,"",(($I14*7 + COLUMN()-COLUMN($B$14)+1) - $K$4 + 1))) | E14: =IF((($I14*7 + COLUMN()-COLUMN($B$14)+1) - $K$4 + 1)<1,"",IF((($I14*7 + COLUMN()-COLUMN($B$14)+1) - $K$4 + 1)>$K$5,"",(($I14*7 + COLUMN()-COLUMN($B$14)+1) - $K$4 + 1))) | F14: =IF((($I14*7 + COLUMN()-COLUMN($B$14)+1) - $K$4 + 1)<1,"",IF((($I14*7 + COLUMN()-COLUMN($B$14)+1) - $K$4 + 1)>$K$5,"",(($I14*7 + COLUMN()-COLUMN($B$14)+1) - $K$4 + 1))) | G14: =IF((($I14*7 + COLUMN()-COLUMN($B$14)+1) - $K$4 + 1)<1,"",IF((($I14*7 + COLUMN()-COLUMN($B$14)+1) - $K$4 + 1)>$K$5,"",(($I14*7 + COLUMN()-COLUMN($B$14)+1) - $K$4 + 1))) | H14: =IF((($I14*7 + COLUMN()-COLUMN($B$14)+1) - $K$4 + 1)<1,"",IF((($I14*7 + COLUMN()-COLUMN($B$14)+1) - $K$4 + 1)>$K$5,"",(($I14*7 + COLUMN()-COLUMN($B$14)+1) - $K$4 + 1))) | I14: 5
B15: =IF(B14="","",IFERROR(VLOOKUP(TEXT(DATE(CONFIG!$B$1,$K$2,B14),"mm-dd"),LECTURAS!$A$2:$B$1000,2,FALSE),"")) | C15: =IF(C14="","",IFERROR(VLOOKUP(TEXT(DATE(CONFIG!$B$1,$K$2,C14),"mm-dd"),LECTURAS!$A$2:$B$1000,2,FALSE),"")) | D15: =IF(D14="","",IFERROR(VLOOKUP(TEXT(DATE(CONFIG!$B$1,$K$2,D14),"mm-dd"),LECTURAS!$A$2:$B$1000,2,FALSE),"")) | E15: =IF(E14="","",IFERROR(VLOOKUP(TEXT(DATE(CONFIG!$B$1,$K$2,E14),"mm-dd"),LECTURAS!$A$2:$B$1000,2,FALSE),"")) | F15: =IF(F14="","",IFERROR(VLOOKUP(TEXT(DATE(CONFIG!$B$1,$K$2,F14),"mm-dd"),LECTURAS!$A$2:$B$1000,2,FALSE),"")) | G15: =IF(G14="","",IFERROR(VLOOKUP(TEXT(DATE(CONFIG!$B$1,$K$2,G14),"mm-dd"),LECTURAS!$A$2:$B$1000,2,FALSE),"")) | H15: =IF(H14="","",IFERROR(VLOOKUP(TEXT(DATE(CONFIG!$B$1,$K$2,H14),"mm-dd"),LECTURAS!$A$2:$B$1000,2,FALSE),"")) | I15: 5

Sheet Marzo
B2: Marzo | K2: 3
B3: Domingo | C3: Lunes | D3: Martes | E3: Miércoles | F3: Jueves | G3: Viernes | H3: Sábado | K3: =DATE(CONFIG!$B$1,$K$2,1) -> 46082
B4: =IF((($I4*7 + COLUMN()-COLUMN($B$4)+1) - $K$4 + 1)<1,"",IF((($I4*7 + COLUMN()-COLUMN($B$4)+1) - $K$4 + 1)>$K$5,"",(($I4*7 + COLUMN()-COLUMN($B$4)+1) - $K$4 + 1))) -> 1 | C4: =IF((($I4*7 + COLUMN()-COLUMN($B$4)+1) - $K$4 + 1)<1,"",IF((($I4*7 + COLUMN()-COLUMN($B$4)+1) - $K$4 + 1)>$K$5,"",(($I4*7 + COLUMN()-COLUMN($B$4)+1) - $K$4 + 1))) -> 2 | D4: =IF((($I4*7 + COLUMN()-COLUMN($B$4)+1) - $K$4 + 1)<1,"",IF((($I4*7 + COLUMN()-COLUMN($B$4)+1) - $K$4 + 1)>$K$5,"",(($I4*7 + COLUMN()-COLUMN($B$4)+1) - $K$4 + 1))) -> 3 | E4: =IF((($I4*7 + COLUMN()-COLUMN($B$4)+1) - $K$4 + 1)<1,"",IF((($I4*7 + COLUMN()-COLUMN($B$4)+1) - $K$4 + 1)>$K$5,"",(($I4*7 + COLUMN()-COLUMN($B$4)+1) - $K$4 + 1))) -> 4 | F4: =IF((($I4*7 + COLUMN()-COLUMN($B$4)+1) - $K$4 + 1)<1,"",IF((($I4*7 + COLUMN()-COLUMN($B$4)+1) - $K$4 + 1)>$K$5,"",(($I4*7 + COLUMN()-COLUMN($B$4)+1) - $K$4 + 1))) -> 5 | G4: =IF((($I4*7 + COLUMN()-COLUMN($B$4)+1) - $K$4 + 1)<1,"",IF((($I4*7 + COLUMN()-COLUMN($B$4)+1) - $K$4 + 1)>$K$5,"",(($I4*7 + COLUMN()-COLUMN($B$4)+1) - $K$4 + 1))) -> 6 | H4: =IF((($I4*7 + COLUMN()-COLUMN($B$4)+1) - $K$4 + 1)<1,"",IF((($I4*7 + COLUMN()-COLUMN($B$4)+1) - $K$4 + 1)>$K$5,"",(($I4*7 + COLUMN()-COLUMN($B$4)+1) - $K$4 + 1))) -> 7 | I4: 0 | K4: =WEEKDAY($K$3,1) -> 1
B5: =IF(B4="","",IFERROR(VLOOKUP(TEXT(DATE(CONFIG!$B$1,$K$2,B4),"mm-dd"),LECTURAS!$A$2:$B$1000,2,FALSE),"")) -> Números 19–20; Hechos 12 | C5: =IF(C4="","",IFERROR(VLOOKUP(TEXT(DATE(CONFIG!$B$1,$K$2,C4),"mm-dd"),LECTURAS!$A$2:$B$1000,2,FALSE),"")) -> Números 21–22; Hechos 13 | D5: =IF(D4="","",IFERROR(VLOOKUP(TEXT(DATE(CONFIG!$B$1,$K$2,D4),"mm-dd"),LECTURAS!$A$2:$B$1000,2,FALSE),"")) -> Números 23–24; Hechos 14 | E5: =IF(E4="","",IFERROR(VLOOKUP(TEXT(DATE(CONFIG!$B$1,$K$2,E4),"mm-dd"),LECTURAS!$A$2:$B$1000,2,FALSE),"")) -> Números 25–26; Hechos 15 | F5: =IF(F4="","",IFERROR(VLOOKUP(TEXT(DATE(CONFIG!$B$1,$K$2,F4),"mm-dd"),LECTURAS!$A$2:$B$1000,2,FALSE),"")) -> Hechos 16–20 | G5: =IF(G4="","",IFERROR(VLOOKUP(TEXT(DATE(CONFIG!$B$1,$K$2,G4),"mm-dd"),LECTURAS!$A$2:$B$1000,2,FALSE),"")) -> Números 27–28; Hechos 21 | H5: =IF(H4="","",IFERROR(VLOOKUP(TEXT(DATE(CONFIG!$B$1,$K$2,H4),"mm-dd"),LECTURAS!$A$2:$B$1000,2,FALSE),"")) -> Números 29–30; Hechos 22 | I5: 0 | K5: =DAY(EOMONTH($K$3,0)) -> 31
B6: =IF((($I6*7 + COLUMN()-COLUMN($B$6)+1) - $K$4 + 1)<1,"",IF((($I6*7 + COLUMN()-COLUMN($B$6)+1) - $K$4 + 1)>$K$5,"",(($I6*7 + COLUMN()-COLUMN($B$6)+1) - $K$4 + 1))) -> 8 | C6: =IF((($I6*7 + COLUMN()-COLUMN($B$6)+1) - $K$4 + 1)<1,"",IF((($I6*7 + COLUMN()-COLUMN($B$6)+1) - $K$4 + 1)>$K$5,"",(($I6*7 + COLUMN()-COLUMN($B$6)+1) - $K$4 + 1))) -> 9 | D6: =IF((($I6*7 + COLUMN()-COLUMN($B$6)+1) - $K$4 + 1)<1,"",IF((($I6*7 + COLUMN()-COLUMN($B$6)+1) - $K$4 + 1)>$K$5,"",(($I6*7 + COLUMN()-COLUMN($B$6)+1) - $K$4 + 1))) -> 10 | E6: =IF((($I6*7 + COLUMN()-COLUMN($B$6)+1) - $K$4 + 1)<1,"",IF((($I6*7 + COLUMN()-COLUMN($B$6)+1) - $K$4 + 1)>$K$5,"",(($I6*7 + COLUMN()-COLUMN($B$6)+1) - $K$4 + 1))) -> 11 | F6: =IF((($I6*7 + COLUMN()-COLUMN($B$6)+1) - $K$4 + 1)<1,"",IF((($I6*7 + COLUMN()-COLUMN($B$6)+1) - $K$4 + 1)>$K$5,"",(($I6*7 + COLUMN()-COLUMN($B$6)+1) - $K$4 + 1))) -> 12 | G6: =IF((($I6*7 + COLUMN()-COLUMN($B$6)+1) - $K$4 + 1)<1,"",IF((($I6*7 + COLUMN()-COLUMN($B$6)+1) - $K$4 + 1)>$K$5,"",(($I6*7 + COLUMN()-COLUMN($B$6)+1) - $K$4 + 1))) -> 13 | H6: =IF((($I6*7 + COLUMN()-COLUMN($B$6)+1) - $K$4 + 1)<1,"",IF((($I6*7 + COLUMN()-COLUMN($B$6)+1) - $K$4 + 1)>$K$5,"",(($I6*7 + COLUMN()-COLUMN($B$6)+1) - $K$4 + 1))) -> 14 | I6: 1
B7: =IF(B6="","",IFERROR(VLOOKUP(TEXT(DATE(CONFIG!$B$1,$K$2,B6),"mm-dd"),LECTURAS!$A$2:$B$1000,2,FALSE),"")) -> Números 31–32; Hechos 23 | C7: =IF(C6="","",IFERROR(VLOOKUP(TEXT(DATE(CONFIG!$B$1,$K$2,C6),"mm-dd"),LECTURAS!$A$2:$B$1000,2,FALSE),"")) -> Números 33; Hechos 24–25 | D7: =IF(D6="","",IFERROR(VLOOKUP(TEXT(DATE(CONFIG!$B$1,$K$2,D6),"mm-dd"),LECTURAS!$A$2:$B$1000,2,FALSE),"")) -> Números 34–35; Hechos 26 | E7: =IF(E6="","",IFERROR(VLOOKUP(TEXT(DATE(CONFIG!$B$1,$K$2,E6),"mm-dd"),LECTURAS!$A$2:$B$1000,2,FALSE),"")) -> Números 36; Hechos 27–28 | F7: =IF(F6="","",IFERROR(VLOOKUP(TEXT(DATE(CONFIG!$B$1,$K$2,F6),"mm-dd"),LECTURAS!$A$2:$B$1000,2,FALSE),"")) -> Deuteronomio 1–3; Mateo 1–2 | G7: =IF(G6="","",IFERROR(VLOOKUP(TEXT(DATE(CONFIG!$B$1,$K$2,G6),"mm-dd"),LECTURAS!$A$2:$B$1000,2,FALSE),"")) -> Deuteronomio 4–6; Mateo 3 | H7: =IF(H6="","",IFERROR(VLOOKUP(TEXT(DATE(CONFIG!$B$1,$K$2,H6),"mm-dd"),LECTURAS!$A$2:$B$1000,2,FALSE),"")) -> Deuteronomio 7–8; Mateo 4 | I7: 1
B8: =IF((($I8*7 + COLUMN()-COLUMN($B$8)+1) - $K$4 + 1)<1,"",IF((($I8*7 + COLUMN()-COLUMN($B$8)+1) - $K$4 + 1)>$K$5,"",(($I8*7 + COLUMN()-COLUMN($B$8)+1) - $K$4 + 1))) -> 15 | C8: =IF((($I8*7 + COLUMN()-COLUMN($B$8)+1) - $K$4 + 1)<1,"",IF((($I8*7 + COLUMN()-COLUMN($B$8)+1) - $K$4 + 1)>$K$5,"",(($I8*7 + COLUMN()-COLUMN($B$8)+1) - $K$4 + 1))) -> 16 | D8: =IF((($I8*7 + COLUMN()-COLUMN($B$8)+1) - $K$4 + 1)<1,"",IF((($I8*7 + COLUMN()-COLUMN($B$8)+1) - $K$4 + 1)>$K$5,"",(($I8*7 + COLUMN()-COLUMN($B$8)+1) - $K$4 + 1))) -> 17 | E8: =IF((($I8*7 + COLUMN()-COLUMN($B$8)+1) - $K$4 + 1)<1,"",IF((($I8*7 + COLUMN()-COLUMN($B$8)+1) - $K$4 + 1)>$K$5,"",(($I8*7 + COLUMN()-COLUMN($B$8)+1) - $K$4 + 1))) -> 18 | F8: =IF((($I8*7 + COLUMN()-COLUMN($B$8)+1) - $K$4 + 1)<1,"",IF((($I8*7 + COLUMN()-COLUMN($B$8)+1) - $K$4 + 1)>$K$5,"",(($I8*7 + COLUMN()-COLUMN($B$8)+1) - $K$4 + 1))) -> 19 | G8: =IF((($I8*7 + COLUMN()-COLUMN($B$8)+1) - $K$4 + 1)<1,"",IF((($I8*7 + COLUMN()-COLUMN($B$8)+1) - $K$4 + 1)>$K$5,"",(($I8*7 + COLUMN()-COLUMN($B$8)+1) - $K$4 + 1))) -> 20 | H8: =IF((($I8*7 + COLUMN()-COLUMN($B$8)+1) - $K$4 + 1)<1,"",IF((($I8*7 + COLUMN()-COLUMN($B$8)+1) - $K$4 + 1)>$K$5,"",(($I8*7 + COLUMN()-COLUMN($B$8)+1) - $K$4 + 1))) -> 21 | I8: 2
B9: =IF(B8="","",IFERROR(VLOOKUP(TEXT(DATE(CONFIG!$B$1,$K$2,B8),"mm-dd"),LECTURAS!$A$2:$B$1000,2,FALSE),"")) -> Deuteronomio 9–10; Mateo 5 | C9: =IF(C8="","",IFERROR(VLOOKUP(TEXT(DATE(CONFIG!$B$1,$K$2,C8),"mm-dd"),LECTURAS!$A$2:$B$1000,2,FALSE),"")) -> Deuteronomio 11–12; Mateo 6 | D9: =IF(D8="","",IFERROR(VLOOKUP(TEXT(DATE(CONFIG!$B$1,$K$2,D8),"mm-dd"),LECTURAS!$A$2:$B$1000,2,FALSE),"")) -> Deuteronomio 13–14; Mateo 7 | E9: =IF(E8="","",IFERROR(VLOOKUP(TEXT(DATE(CONFIG!$B$1,$K$2,E8),"mm-dd"),LECTURAS!$A$2:$B$1000,2,FALSE),"")) -> Deuteronomio 15–16; Mateo 8 | F9: =IF(F8="","",IFERROR(VLOOKUP(TEXT(DATE(CONFIG!$B$1,$K$2,F8),"mm-dd"),LECTURAS!$A$2:$B$1000,2,FALSE),"")) -> Deuteronomio 17; Mateo 9–12 | G9: =IF(G8="","",IFERROR(VLOOKUP(TEXT(DATE(CONFIG!$B$1,$K$2,G8),"mm-dd"),LECTURAS!$A$2:$B$1000,2,FALSE),"")) -> Deuteronomio 18; Mateo 13–14 | H9: =IF(H8="","",IFERROR(VLOOKUP(TEXT(DATE(CONFIG!$B$1,$K$2,H8),"mm-dd"),LECTURAS!$A$2:$B$1000,2,FALSE),"")) -> Deuteronomio 19; Mateo 15–16 | I9: 2
B10: =IF((($I10*7 + COLUMN()-COLUMN($B$10)+1) - $K$4 + 1)<1,"",IF((($I10*7 + COLUMN()-COLUMN($B$10)+1) - $K$4 + 1)>$K$5,"",(($I10*7 + COLUMN()-COLUMN($B$10)+1) - $K$4 + 1))) -> 22 | C10: =IF((($I10*7 + COLUMN()-COLUMN($B$10)+1) - $K$4 + 1)<1,"",IF((($I10*7 + COLUMN()-COLUMN($B$10)+1) - $K$4 + 1)>$K$5,"",(($I10*7 + COLUMN()-COLUMN($B$10)+1) - $K$4 + 1))) -> 23 | D10: =IF((($I10*7 + COLUMN()-COLUMN($B$10)+1) - $K$4 + 1)<1,"",IF((($I10*7 + COLUMN()-COLUMN($B$10)+1) - $K$4 + 1)>$K$5,"",(($I10*7 + COLUMN()-COLUMN($B$10)+1) - $K$4 + 1))) -> 24 | E10: =IF((($I10*7 + COLUMN()-COLUMN($B$10)+1) - $K$4 + 1)<1,"",IF((($I10*7 + COLUMN()-COLUMN($B$10)+1) - $K$4 + 1)>$K$5,"",(($I10*7 + COLUMN()-COLUMN($B$10)+1) - $K$4 + 1))) -> 25 | F10: =IF((($I10*7 + COLUMN()-COLUMN($B$10)+1) - $K$4 + 1)<1,"",IF((($I10*7 + COLUMN()-COLUMN($B$10)+1) - $K$4 + 1)>$K$5,"",(($I10*7 + COLUMN()-COLUMN($B$10)+1) - $K$4 + 1))) -> 26 | G10: =IF((($I10*7 + COLUMN()-COLUMN($B$10)+1) - $K$4 + 1)<1,"",IF((($I10*7 + COLUMN()-COLUMN($B$10)+1) - $K$4 + 1)>$K$5,"",(($I10*7 + COLUMN()-COLUMN($B$10)+1) - $K$4 + 1))) -> 27 | H10: =IF((($I10*7 + COLUMN()-COLUMN($B$10)+1) - $K$4 + 1)<1,"",IF((($I10*7 + COLUMN()-COLUMN($B$10)+1) - $K$4 + 1)>$K$5,"",(($I10*7 + COLUMN()-COLUMN($B$10)+1) - $K$4 + 1))) -> 28 | I10: 3
B11: =IF(B10="","",IFERROR(VLOOKUP(TEXT(DATE(CONFIG!$B$1,$K$2,B10),"mm-dd"),LECTURAS!$A$2:$B$1000,2,FALSE),"")) -> Deuteronomio 20–21; Mateo 17 | C11: =IF(C10="","",IFERROR(VLOOKUP(TEXT(DATE(CONFIG!$B$1,$K$2,C10),"mm-dd"),LECTURAS!$A$2:$B$1000,2,FALSE),"")) -> Deuteronomio 22–23; Mateo 18 | D11: =IF(D10="","",IFERROR(VLOOKUP(TEXT(DATE(CONFIG!$B$1,$K$2,D10),"mm-dd"),LECTURAS!$A$2:$B$1000,2,FALSE),"")) -> Deuteronomio 24; Mateo 19–20 | E11: =IF(E10="","",IFERROR(VLOOKUP(TEXT(DATE(CONFIG!$B$1,$K$2,E10),"mm-dd"),LECTURAS!$A$2:$B$1000,2,FALSE),"")) -> Deuteronomio 25–26; Mateo 21 | F11: =IF(F10="","",IFERROR(VLOOKUP(TEXT(DATE(CONFIG!$B$1,$K$2,F10),"mm-dd"),LECTURAS!$A$2:$B$1000,2,FALSE),"")) -> Deuteronomio 27; Mateo 22–25 | G11: =IF(G10="","",IFERROR(VLOOKUP(TEXT(DATE(CONFIG!$B$1,$K$2,G10),"mm-dd"),LECTURAS!$A$2:$B$1000,2,FALSE),"")) -> Deuteronomio 28–29; Mateo 26 | H11: =IF(H10="","",IFERROR(VLOOKUP(TEXT(DATE(CONFIG!$B$1,$K$2,H10),"mm-dd"),LECTURAS!$A$2:$B$1000,2,FALSE),"")) -> Deuteronomio 30–31; Mateo 27 | I11: 3
B12: =IF((($I12*7 + COLUMN()-COLUMN($B$12)+1) - $K$4 + 1)<1,"",IF((($I12*7 + COLUMN()-COLUMN($B$12)+1) - $K$4 + 1)>$K$5,"",(($I12*7 + COLUMN()-COLUMN($B$12)+1) - $K$4 + 1))) -> 29 | C12: =IF((($I12*7 + COLUMN()-COLUMN($B$12)+1) - $K$4 + 1)<1,"",IF((($I12*7 + COLUMN()-COLUMN($B$12)+1) - $K$4 + 1)>$K$5,"",(($I12*7 + COLUMN()-COLUMN($B$12)+1) - $K$4 + 1))) -> 30 | D12: =IF((($I12*7 + COLUMN()-COLUMN($B$12)+1) - $K$4 + 1)<1,"",IF((($I12*7 + COLUMN()-COLUMN($B$12)+1) - $K$4 + 1)>$K$5,"",(($I12*7 + COLUMN()-COLUMN($B$12)+1) - $K$4 + 1))) -> 31 | E12: =IF((($I12*7 + COLUMN()-COLUMN($B$12)+1) - $K$4 + 1)<1,"",IF((($I12*7 + COLUMN()-COLUMN($B$12)+1) - $K$4 + 1)>$K$5,"",(($I12*7 + COLUMN()-COLUMN($B$12)+1) - $K$4 + 1))) | F12: =IF((($I12*7 + COLUMN()-COLUMN($B$12)+1) - $K$4 + 1)<1,"",IF((($I12*7 + COLUMN()-COLUMN($B$12)+1) - $K$4 + 1)>$K$5,"",(($I12*7 + COLUMN()-COLUMN($B$12)+1) - $K$4 + 1))) | G12: =IF((($I12*7 + COLUMN()-COLUMN($B$12)+1) - $K$4 + 1)<1,"",IF((($I12*7 + COLUMN()-COLUMN($B$12)+1) - $K$4 + 1)>$K$5,"",(($I12*7 + COLUMN()-COLUMN($B$12)+1) - $K$4 + 1))) | H12: =IF((($I12*7 + COLUMN()-COLUMN($B$12)+1) - $K$4 + 1)<1,"",IF((($I12*7 + COLUMN()-COLUMN($B$12)+1) - $K$4 + 1)>$K$5,"",(($I12*7 + COLUMN()-COLUMN($B$12)+1) - $K$4 + 1))) | I12: 4
B13: =IF(B12="","",IFERROR(VLOOKUP(TEXT(DATE(CONFIG!$B$1,$K$2,B12),"mm-dd"),LECTURAS!$A$2:$B$1000,2,FALSE),"")) -> Deuteronomio 32–34; Mateo 28 | C13: =IF(C12="","",IFERROR(VLOOKUP(TEXT(DATE(CONFIG!$B$1,$K$2,C12),"mm-dd"),LECTURAS!$A$2:$B$1000,2,FALSE),"")) -> Josué 1–2; Proverbios 1 | D13: =IF(D12="","",IFERROR(VLOOKUP(TEXT(DATE(CONFIG!$B$1,$K$2,D12),"mm-dd"),LECTURAS!$A$2:$B$1000,2,FALSE),"")) -> Josué 3–4; Proverbios 2 | E13: =IF(E12="","",IFERROR(VLOOKUP(TEXT(DATE(CONFIG!$B$1,$K$2,E12),"mm-dd"),LECTURAS!$A$2:$B$1000,2,FALSE),"")) | F13: =IF(F12="","",IFERROR(VLOOKUP(TEXT(DATE(CONFIG!$B$1,$K$2,F12),"mm-dd"),LECTURAS!$A$2:$B$1000,2,FALSE),"")) | G13: =IF(G12="","",IFERROR(VLOOKUP(TEXT(DATE(CONFIG!$B$1,$K$2,G12),"mm-dd"),LECTURAS!$A$2:$B$1000,2,FALSE),"")) | H13: =IF(H12="","",IFERROR(VLOOKUP(TEXT(DATE(CONFIG!$B$1,$K$2,H12),"mm-dd"),LECTURAS!$A$2:$B$1000,2,FALSE),"")) | I13: 4
B14: =IF((($I14*7 + COLUMN()-COLUMN($B$14)+1) - $K$4 + 1)<1,"",IF((($I14*7 + COLUMN()-COLUMN($B$14)+1) - $K$4 + 1)>$K$5,"",(($I14*7 + COLUMN()-COLUMN($B$14)+1) - $K$4 + 1))) | C14: =IF((($I14*7 + COLUMN()-COLUMN($B$14)+1) - $K$4 + 1)<1,"",IF((($I14*7 + COLUMN()-COLUMN($B$14)+1) - $K$4 + 1)>$K$5,"",(($I14*7 + COLUMN()-COLUMN($B$14)+1) - $K$4 + 1))) | D14: =IF((($I14*7 + COLUMN()-COLUMN($B$14)+1) - $K$4 + 1)<1,"",IF((($I14*7 + COLUMN()-COLUMN($B$14)+1) - $K$4 + 1)>$K$5,"",(($I14*7 + COLUMN()-COLUMN($B$14)+1) - $K$4 + 1))) | E14: =IF((($I14*7 + COLUMN()-COLUMN($B$14)+1) - $K$4 + 1)<1,"",IF((($I14*7 + COLUMN()-COLUMN($B$14)+1) - $K$4 + 1)>$K$5,"",(($I14*7 + COLUMN()-COLUMN($B$14)+1) - $K$4 + 1))) | F14: =IF((($I14*7 + COLUMN()-COLUMN($B$14)+1) - $K$4 + 1)<1,"",IF((($I14*7 + COLUMN()-COLUMN($B$14)+1) - $K$4 + 1)>$K$5,"",(($I14*7 + COLUMN()-COLUMN($B$14)+1) - $K$4 + 1))) | G14: =IF((($I14*7 + COLUMN()-COLUMN($B$14)+1) - $K$4 + 1)<1,"",IF((($I14*7 + COLUMN()-COLUMN($B$14)+1) - $K$4 + 1)>$K$5,"",(($I14*7 + COLUMN()-COLUMN($B$14)+1) - $K$4 + 1))) | H14: =IF((($I14*7 + COLUMN()-COLUMN($B$14)+1) - $K$4 + 1)<1,"",IF((($I14*7 + COLUMN()-COLUMN($B$14)+1) - $K$4 + 1)>$K$5,"",(($I14*7 + COLUMN()-COLUMN($B$14)+1) - $K$4 + 1))) | I14: 5
B15: =IF(B14="","",IFERROR(VLOOKUP(TEXT(DATE(CONFIG!$B$1,$K$2,B14),"mm-dd"),LECTURAS!$A$2:$B$1000,2,FALSE),"")) | C15: =IF(C14="","",IFERROR(VLOOKUP(TEXT(DATE(CONFIG!$B$1,$K$2,C14),"mm-dd"),LECTURAS!$A$2:$B$1000,2,FALSE),"")) | D15: =IF(D14="","",IFERROR(VLOOKUP(TEXT(DATE(CONFIG!$B$1,$K$2,D14),"mm-dd"),LECTURAS!$A$2:$B$1000,2,FALSE),"")) | E15: =IF(E14="","",IFERROR(VLOOKUP(TEXT(DATE(CONFIG!$B$1,$K$2,E14),"mm-dd"),LECTURAS!$A$2:$B$1000,2,FALSE),"")) | F15: =IF(F14="","",IFERROR(VLOOKUP(TEXT(DATE(CONFIG!$B$1,$K$2,F14),"mm-dd"),LECTURAS!$A$2:$B$1000,2,FALSE),"")) | G15: =IF(G14="","",IFERROR(VLOOKUP(TEXT(DATE(CONFIG!$B$1,$K$2,G14),"mm-dd"),LECTURAS!$A$2:$B$1000,2,FALSE),"")) | H15: =IF(H14="","",IFERROR(VLOOKUP(TEXT(DATE(CONFIG!$B$1,$K$2,H14),"mm-dd"),LECTURAS!$A$2:$B$1000,2,FALSE),"")) | I15: 5

Sheet Abril
B2: Abril | K2: 4
B3: Domingo | C3: Lunes | D3: Martes | E3: Miércoles | F3: Jueves | G3: Viernes | H3: Sábado | K3: =DATE(CONFIG!$B$1,$K$2,1) -> 46113
B4: =IF((($I4*7 + COLUMN()-COLUMN($B$4)+1) - $K$4 + 1)<1,"",IF((($I4*7 + COLUMN()-COLUMN($B$4)+1) - $K$4 + 1)>$K$5,"",(($I4*7 + COLUMN()-COLUMN($B$4)+1) - $K$4 + 1))) | C4: =IF((($I4*7 + COLUMN()-COLUMN($B$4)+1) - $K$4 + 1)<1,"",IF((($I4*7 + COLUMN()-COLUMN($B$4)+1) - $K$4 + 1)>$K$5,"",(($I4*7 + COLUMN()-COLUMN($B$4)+1) - $K$4 + 1))) | D4: =IF((($I4*7 + COLUMN()-COLUMN($B$4)+1) - $K$4 + 1)<1,"",IF((($I4*7 + COLUMN()-COLUMN($B$4)+1) - $K$4 + 1)>$K$5,"",(($I4*7 + COLUMN()-COLUMN($B$4)+1) - $K$4 + 1))) | E4: =IF((($I4*7 + COLUMN()-COLUMN($B$4)+1) - $K$4 + 1)<1,"",IF((($I4*7 + COLUMN()-COLUMN($B$4)+1) - $K$4 + 1)>$K$5,"",(($I4*7 + COLUMN()-COLUMN($B$4)+1) - $K$4 + 1))) -> 1 | F4: =IF((($I4*7 + COLUMN()-COLUMN($B$4)+1) - $K$4 + 1)<1,"",IF((($I4*7 + COLUMN()-COLUMN($B$4)+1) - $K$4 + 1)>$K$5,"",(($I4*7 + COLUMN()-COLUMN($B$4)+1) - $K$4 + 1))) -> 2 | G4: =IF((($I4*7 + COLUMN()-COLUMN($B$4)+1) - $K$4 + 1)<1,"",IF((($I4*7 + COLUMN()-COLUMN($B$4)+1) - $K$4 + 1)>$K$5,"",(($I4*7 + COLUMN()-COLUMN($B$4)+1) - $K$4 + 1))) -> 3 | H4: =IF((($I4*7 + COLUMN()-COLUMN($B$4)+1) - $K$4 + 1)<1,"",IF((($I4*7 + COLUMN()-COLUMN($B$4)+1) - $K$4 + 1)>$K$5,"",(($I4*7 + COLUMN()-COLUMN($B$4)+1) - $K$4 + 1))) -> 4 | I4: 0 | K4: =WEEKDAY($K$3,1) -> 4
B5: =IF(B4="","",IFERROR(VLOOKUP(TEXT(DATE(CONFIG!$B$1,$K$2,B4),"mm-dd"),LECTURAS!$A$2:$B$1000,2,FALSE),"")) | C5: =IF(C4="","",IFERROR(VLOOKUP(TEXT(DATE(CONFIG!$B$1,$K$2,C4),"mm-dd"),LECTURAS!$A$2:$B$1000,2,FALSE),"")) | D5: =IF(D4="","",IFERROR(VLOOKUP(TEXT(DATE(CONFIG!$B$1,$K$2,D4),"mm-dd"),LECTURAS!$A$2:$B$1000,2,FALSE),"")) | E5: =IF(E4="","",IFERROR(VLOOKUP(TEXT(DATE(CONFIG!$B$1,$K$2,E4),"mm-dd"),LECTURAS!$A$2:$B$1000,2,FALSE),"")) -> Josué 5–6; Proverbios 3 | F5: =IF(F4="","",IFERROR(VLOOKUP(TEXT(DATE(CONFIG!$B$1,$K$2,F4),"mm-dd"),LECTURAS!$A$2:$B$1000,2,FALSE),"")) -> Josué 7–9; Proverbios 4–5 | G5: =IF(G4="","",IFERROR(VLOOKUP(TEXT(DATE(CONFIG!$B$1,$K$2,G4),"mm-dd"),LECTURAS!$A$2:$B$1000,2,FALSE),"")) -> Josué 10–11; Proverbios 6 | H5: =IF(H4="","",IFERROR(VLOOKUP(TEXT(DATE(CONFIG!$B$1,$K$2,H4),"mm-dd"),LECTURAS!$A$2:$B$1000,2,FALSE),"")) -> Josué 12–13; Proverbios 7 | I5: 0 | K5: =DAY(EOMONTH($K$3,0)) -> 30
B6: =IF((($I6*7 + COLUMN()-COLUMN($B$6)+1) - $K$4 + 1)<1,"",IF((($I6*7 + COLUMN()-COLUMN($B$6)+1) - $K$4 + 1)>$K$5,"",(($I6*7 + COLUMN()-COLUMN($B$6)+1) - $K$4 + 1))) -> 5 | C6: =IF((($I6*7 + COLUMN()-COLUMN($B$6)+1) - $K$4 + 1)<1,"",IF((($I6*7 + COLUMN()-COLUMN($B$6)+1) - $K$4 + 1)>$K$5,"",(($I6*7 + COLUMN()-COLUMN($B$6)+1) - $K$4 + 1))) -> 6 | D6: =IF((($I6*7 + COLUMN()-COLUMN($B$6)+1) - $K$4 + 1)<1,"",IF((($I6*7 + COLUMN()-COLUMN($B$6)+1) - $K$4 + 1)>$K$5,"",(($I6*7 + COLUMN()-COLUMN($B$6)+1) - $K$4 + 1))) -> 7 | E6: =IF((($I6*7 + COLUMN()-COLUMN($B$6)+1) - $K$4 + 1)<1,"",IF((($I6*7 + COLUMN()-COLUMN($B$6)+1) - $K$4 + 1)>$K$5,"",(($I6*7 + COLUMN()-COLUMN($B$6)+1) - $K$4 + 1))) -> 8 | F6: =IF((($I6*7 + COLUMN()-COLUMN($B$6)+1) - $K$4 + 1)<1,"",IF((($I6*7 + COLUMN()-COLUMN($B$6)+1) - $K$4 + 1)>$K$5,"",(($I6*7 + COLUMN()-COLUMN($B$6)+1) - $K$4 + 1))) -> 9 | G6: =IF((($I6*7 + COLUMN()-COLUMN($B$6)+1) - $K$4 + 1)<1,"",IF((($I6*7 + COLUMN()-COLUMN($B$6)+1) - $K$4 + 1)>$K$5,"",(($I6*7 + COLUMN()-COLUMN($B$6)+1) - $K$4 + 1))) -> 10 | H6: =IF((($I6*7 + COLUMN()-COLUMN($B$6)+1) - $K$4 + 1)<1,"",IF((($I6*7 + COLUMN()-COLUMN($B$6)+1) - $K$4 + 1)>$K$5,"",(($I6*7 + COLUMN()-COLUMN($B$6)+1) - $K$4 + 1))) -> 11 | I6: 1
B7: =IF(B6="","",IFERROR(VLOOKUP(TEXT(DATE(CONFIG!$B$1,$K$2,B6),"mm-dd"),LECTURAS!$A$2:$B$1000,2,FALSE),"")) -> Josué 14–15; Proverbios 8 | C7: =IF(C6="","",IFERROR(VLOOKUP(TEXT(DATE(CONFIG!$B$1,$K$2,C6),"mm-dd"),LECTURAS!$A$2:$B$1000,2,FALSE),"")) -> Josué 16–17; Proverbios 9 | D7: =IF(D6="","",IFERROR(VLOOKUP(TEXT(DATE(CONFIG!$B$1,$K$2,D6),"mm-dd"),LECTURAS!$A$2:$B$1000,2,FALSE),"")) -> Josué 18–19; Proverbios 10 | E7: =IF(E6="","",IFERROR(VLOOKUP(TEXT(DATE(CONFIG!$B$1,$K$2,E6),"mm-dd"),LECTURAS!$A$2:$B$1000,2,FALSE),"")) -> Josué 20–21; Proverbios 11 | F7: =IF(F6="","",IFERROR(VLOOKUP(TEXT(DATE(CONFIG!$B$1,$K$2,F6),"mm-dd"),LECTURAS!$A$2:$B$1000,2,FALSE),"")) -> Josué 22–24; Proverbios 12–13 | G7: =IF(G6="","",IFERROR(VLOOKUP(TEXT(DATE(CONFIG!$B$1,$K$2,G6),"mm-dd"),LECTURAS!$A$2:$B$1000,2,FALSE),"")) -> Jueces 1–2; Proverbios 14 | H7: =IF(H6="","",IFERROR(VLOOKUP(TEXT(DATE(CONFIG!$B$1,$K$2,H6),"mm-dd"),LECTURAS!$A$2:$B$1000,2,FALSE),"")) -> Jueces 3–4; Proverbios 15 | I7: 1
B8: =IF((($I8*7 + COLUMN()-COLUMN($B$8)+1) - $K$4 + 1)<1,"",IF((($I8*7 + COLUMN()-COLUMN($B$8)+1) - $K$4 + 1)>$K$5,"",(($I8*7 + COLUMN()-COLUMN($B$8)+1) - $K$4 + 1))) -> 12 | C8: =IF((($I8*7 + COLUMN()-COLUMN($B$8)+1) - $K$4 + 1)<1,"",IF((($I8*7 + COLUMN()-COLUMN($B$8)+1) - $K$4 + 1)>$K$5,"",(($I8*7 + COLUMN()-COLUMN($B$8)+1) - $K$4 + 1))) -> 13 | D8: =IF((($I8*7 + COLUMN()-COLUMN($B$8)+1) - $K$4 + 1)<1,"",IF((($I8*7 + COLUMN()-COLUMN($B$8)+1) - $K$4 + 1)>$K$5,"",(($I8*7 + COLUMN()-COLUMN($B$8)+1) - $K$4 + 1))) -> 14 | E8: =IF((($I8*7 + COLUMN()-COLUMN($B$8)+1) - $K$4 + 1)<1,"",IF((($I8*7 + COLUMN()-COLUMN($B$8)+1) - $K$4 + 1)>$K$5,"",(($I8*7 + COLUMN()-COLUMN($B$8)+1) - $K$4 + 1))) -> 15 | F8: =IF((($I8*7 + COLUMN()-COLUMN($B$8)+1) - $K$4 + 1)<1,"",IF((($I8*7 + COLUMN()-COLUMN($B$8)+1) - $K$4 + 1)>$K$5,"",(($I8*7 + COLUMN()-COLUMN($B$8)+1) - $K$4 + 1))) -> 16 | G8: =IF((($I8*7 + COLUMN()-COLUMN($B$8)+1) - $K$4 + 1)<1,"",IF((($I8*7 + COLUMN()-COLUMN($B$8)+1) - $K$4 + 1)>$K$5,"",(($I8*7 + COLUMN()-COLUMN($B$8)+1) - $K$4 + 1))) -> 17 | H8: =IF((($I8*7 + COLUMN()-COLUMN($B$8)+1) - $K$4 + 1)<1,"",IF((($I8*7 + COLUMN()-COLUMN($B$8)+1) - $K$4 + 1)>$K$5,"",(($I8*7 + COLUMN()-COLUMN($B$8)+1) - $K$4 + 1))) -> 18 | I8: 2
B9: =IF(B8="","",IFERROR(VLOOKUP(TEXT(DATE(CONFIG!$B$1,$K$2,B8),"mm-dd"),LECTURAS!$A$2:$B$1000,2,FALSE),"")) -> Jueces 5–6; Proverbios 16 | C9: =IF(C8="","",IFERROR(VLOOKUP(TEXT(DATE(CONFIG!$B$1,$K$2,C8),"mm-dd"),LECTURAS!$A$2:$B$1000,2,FALSE),"")) -> Jueces 7–8; Proverbios 17 | D9: =IF(D8="","",IFERROR(VLOOKUP(TEXT(DATE(CONFIG!$B$1,$K$2,D8),"mm-dd"),LECTURAS!$A$2:$B$1000,2,FALSE),"")) -> Jueces 9–10; Proverbios 18 | E9: =IF(E8="","",IFERROR(VLOOKUP(TEXT(DATE(CONFIG!$B$1,$K$2,E8),"mm-dd"),LECTURAS!$A$2:$B$1000,2,FALSE),"")) -> Jueces 11–12; Proverbios 19 | F9: =IF(F8="","",IFERROR(VLOOKUP(TEXT(DATE(CONFIG!$B$1,$K$2,F8),"mm-dd"),LECTURAS!$A$2:$B$1000,2,FALSE),"")) -> Jueces 13–15; Proverbios 20–21 | G9: =IF(G8="","",IFERROR(VLOOKUP(TEXT(DATE(CONFIG!$B$1,$K$2,G8),"mm-dd"),LECTURAS!$A$2:$B$1000,2,FALSE),"")) -> Jueces 16–17; Proverbios 22 | H9: =IF(H8="","",IFERROR(VLOOKUP(TEXT(DATE(CONFIG!$B$1,$K$2,H8),"mm-dd"),LECTURAS!$A$2:$B$1000,2,FALSE),"")) -> Jueces 18–19; Proverbios 23 | I9: 2
B10: =IF((($I10*7 + COLUMN()-COLUMN($B$10)+1) - $K$4 + 1)<1,"",IF((($I10*7 + COLUMN()-COLUMN($B$10)+1) - $K$4 + 1)>$K$5,"",(($I10*7 + COLUMN()-COLUMN($B$10)+1) - $K$4 + 1))) -> 19 | C10: =IF((($I10*7 + COLUMN()-COLUMN($B$10)+1) - $K$4 + 1)<1,"",IF((($I10*7 + COLUMN()-COLUMN($B$10)+1) - $K$4 + 1)>$K$5,"",(($I10*7 + COLUMN()-COLUMN($B$10)+1) - $K$4 + 1))) -> 20 | D10: =IF((($I10*7 + COLUMN()-COLUMN($B$10)+1) - $K$4 + 1)<1,"",IF((($I10*7 + COLUMN()-COLUMN($B$10)+1) - $K$4 + 1)>$K$5,"",(($I10*7 + COLUMN()-COLUMN($B$10)+1) - $K$4 + 1))) -> 21 | E10: =IF((($I10*7 + COLUMN()-COLUMN($B$10)+1) - $K$4 + 1)<1,"",IF((($I10*7 + COLUMN()-COLUMN($B$10)+1) - $K$4 + 1)>$K$5,"",(($I10*7 + COLUMN()-COLUMN($B$10)+1) - $K$4 + 1))) -> 22 | F10: =IF((($I10*7 + COLUMN()-COLUMN($B$10)+1) - $K$4 + 1)<1,"",IF((($I10*7 + COLUMN()-COLUMN($B$10)+1) - $K$4 + 1)>$K$5,"",(($I10*7 + COLUMN()-COLUMN($B$10)+1) - $K$4 + 1))) -> 23 | G10: =IF((($I10*7 + COLUMN()-COLUMN($B$10)+1) - $K$4 + 1)<1,"",IF((($I10*7 + COLUMN()-COLUMN($B$10)+1) - $K$4 + 1)>$K$5,"",(($I10*7 + COLUMN()-COLUMN($B$10)+1) - $K$4 + 1))) -> 24 | H10: =IF((($I10*7 + COLUMN()-COLUMN($B$10)+1) - $K$4 + 1)<1,"",IF((($I10*7 + COLUMN()-COLUMN($B$10)+1) - $K$4 + 1)>$K$5,"",(($I10*7 + COLUMN()-COLUMN($B$10)+1) - $K$4 + 1))) -> 25 | I10: 3
B11: =IF(B10="","",IFERROR(VLOOKUP(TEXT(DATE(CONFIG!$B$1,$K$2,B10),"mm-dd"),LECTURAS!$A$2:$B$1000,2,FALSE),"")) -> Jueces 20–21; Proverbios 24 | C11: =IF(C10="","",IFERROR(VLOOKUP(TEXT(DATE(CONFIG!$B$1,$K$2,C10),"mm-dd"),LECTURAS!$A$2:$B$1000,2,FALSE),"")) -> Rut 1–2; Proverbios 25 | D11: =IF(D10="","",IFERROR(VLOOKUP(TEXT(DATE(CONFIG!$B$1,$K$2,D10),"mm-dd"),LECTURAS!$A$2:$B$1000,2,FALSE),"")) -> Rut 3–4; Proverbios 26 | E11: =IF(E10="","",IFERROR(VLOOKUP(TEXT(DATE(CONFIG!$B$1,$K$2,E10),"mm-dd"),LECTURAS!$A$2:$B$1000,2,FALSE),"")) -> 1 Samuel 1–2; Proverbios 27 | F11: =IF(F10="","",IFERROR(VLOOKUP(TEXT(DATE(CONFIG!$B$1,$K$2,F10),"mm-dd"),LECTURAS!$A$2:$B$1000,2,FALSE),"")) -> 1 Samuel 3; Proverbios 28–29 | G11: =IF(G10="","",IFERROR(VLOOKUP(TEXT(DATE(CONFIG!$B$1,$K$2,G10),"mm-dd"),LECTURAS!$A$2:$B$1000,2,FALSE),"")) -> 1 Samuel 4–5; Proverbios 30 | H11: =IF(H10="","",IFERROR(VLOOKUP(TEXT(DATE(CONFIG!$B$1,$K$2,H10),"mm-dd"),LECTURAS!$A$2:$B$1000,2,FALSE),"")) -> 1 Samuel 6–7; Proverbios 31 | I11: 3
B12: =IF((($I12*7 + COLUMN()-COLUMN($B$12)+1) - $K$4 + 1)<1,"",IF((($I12*7 + COLUMN()-COLUMN($B$12)+1) - $K$4 + 1)>$K$5,"",(($I12*7 + COLUMN()-COLUMN($B$12)+1) - $K$4 + 1))) -> 26 | C12: =IF((($I12*7 + COLUMN()-COLUMN($B$12)+1) - $K$4 + 1)<1,"",IF((($I12*7 + COLUMN()-COLUMN($B$12)+1) - $K$4 + 1)>$K$5,"",(($I12*7 + COLUMN()-COLUMN($B$12)+1) - $K$4 + 1))) -> 27 | D12: =IF((($I12*7 + COLUMN()-COLUMN($B$12)+1) - $K$4 + 1)<1,"",IF((($I12*7 + COLUMN()-COLUMN($B$12)+1) - $K$4 + 1)>$K$5,"",(($I12*7 + COLUMN()-COLUMN($B$12)+1) - $K$4 + 1))) -> 28 | E12: =IF((($I12*7 + COLUMN()-COLUMN($B$12)+1) - $K$4 + 1)<1,"",IF((($I12*7 + COLUMN()-COLUMN($B$12)+1) - $K$4 + 1)>$K$5,"",(($I12*7 + COLUMN()-COLUMN($B$12)+1) - $K$4 + 1))) -> 29 | F12: =IF((($I12*7 + COLUMN()-COLUMN($B$12)+1) - $K$4 + 1)<1,"",IF((($I12*7 + COLUMN()-COLUMN($B$12)+1) - $K$4 + 1)>$K$5,"",(($I12*7 + COLUMN()-COLUMN($B$12)+1) - $K$4 + 1))) -> 30 | G12: =IF((($I12*7 + COLUMN()-COLUMN($B$12)+1) - $K$4 + 1)<1,"",IF((($I12*7 + COLUMN()-COLUMN($B$12)+1) - $K$4 + 1)>$K$5,"",(($I12*7 + COLUMN()-COLUMN($B$12)+1) - $K$4 + 1))) | H12: =IF((($I12*7 + COLUMN()-COLUMN($B$12)+1) - $K$4 + 1)<1,"",IF((($I12*7 + COLUMN()-COLUMN($B$12)+1) - $K$4 + 1)>$K$5,"",(($I12*7 + COLUMN()-COLUMN($B$12)+1) - $K$4 + 1))) | I12: 4
B13: =IF(B12="","",IFERROR(VLOOKUP(TEXT(DATE(CONFIG!$B$1,$K$2,B12),"mm-dd"),LECTURAS!$A$2:$B$1000,2,FALSE),"")) -> 1 Samuel 8–9; Salmo 1 | C13: =IF(C12="","",IFERROR(VLOOKUP(TEXT(DATE(CONFIG!$B$1,$K$2,C12),"mm-dd"),LECTURAS!$A$2:$B$1000,2,FALSE),"")) -> 1 Samuel 10–11; Salmo 2 | D13: =IF(D12="","",IFERROR(VLOOKUP(TEXT(DATE(CONFIG!$B$1,$K$2,D12),"mm-dd"),LECTURAS!$A$2:$B$1000,2,FALSE),"")) -> 1 Samuel 12–13; Salmo 3–4 | E13: =IF(E12="","",IFERROR(VLOOKUP(TEXT(DATE(CONFIG!$B$1,$K$2,E12),"mm-dd"),LECTURAS!$A$2:$B$1000,2,FALSE),"")) -> 1 Samuel 14–15; Salmo 5–6 | F13: =IF(F12="","",IFERROR(VLOOKUP(TEXT(DATE(CONFIG!$B$1,$K$2,F12),"mm-dd"),LECTURAS!$A$2:$B$1000,2,FALSE),"")) -> 1 Samuel 16–17; Salmo 7–9 | G13: =IF(G12="","",IFERROR(VLOOKUP(TEXT(DATE(CONFIG!$B$1,$K$2,G12),"mm-dd"),LECTURAS!$A$2:$B$1000,2,FALSE),"")) | H13: =IF(H12="","",IFERROR(VLOOKUP(TEXT(DATE(CONFIG!$B$1,$K$2,H12),"mm-dd"),LECTURAS!$A$2:$B$1000,2,FALSE),"")) | I13: 4
B14: =IF((($I14*7 + COLUMN()-COLUMN($B$14)+1) - $K$4 + 1)<1,"",IF((($I14*7 + COLUMN()-COLUMN($B$14)+1) - $K$4 + 1)>$K$5,"",(($I14*7 + COLUMN()-COLUMN($B$14)+1) - $K$4 + 1))) | C14: =IF((($I14*7 + COLUMN()-COLUMN($B$14)+1) - $K$4 + 1)<1,"",IF((($I14*7 + COLUMN()-COLUMN($B$14)+1) - $K$4 + 1)>$K$5,"",(($I14*7 + COLUMN()-COLUMN($B$14)+1) - $K$4 + 1))) | D14: =IF((($I14*7 + COLUMN()-COLUMN($B$14)+1) - $K$4 + 1)<1,"",IF((($I14*7 + COLUMN()-COLUMN($B$14)+1) - $K$4 + 1)>$K$5,"",(($I14*7 + COLUMN()-COLUMN($B$14)+1) - $K$4 + 1))) | E14: =IF((($I14*7 + COLUMN()-COLUMN($B$14)+1) - $K$4 + 1)<1,"",IF((($I14*7 + COLUMN()-COLUMN($B$14)+1) - $K$4 + 1)>$K$5,"",(($I14*7 + COLUMN()-COLUMN($B$14)+1) - $K$4 + 1))) | F14: =IF((($I14*7 + COLUMN()-COLUMN($B$14)+1) - $K$4 + 1)<1,"",IF((($I14*7 + COLUMN()-COLUMN($B$14)+1) - $K$4 + 1)>$K$5,"",(($I14*7 + COLUMN()-COLUMN($B$14)+1) - $K$4 + 1))) | G14: =IF((($I14*7 + COLUMN()-COLUMN($B$14)+1) - $K$4 + 1)<1,"",IF((($I14*7 + COLUMN()-COLUMN($B$14)+1) - $K$4 + 1)>$K$5,"",(($I14*7 + COLUMN()-COLUMN($B$14)+1) - $K$4 + 1))) | H14: =IF((($I14*7 + COLUMN()-COLUMN($B$14)+1) - $K$4 + 1)<1,"",IF((($I14*7 + COLUMN()-COLUMN($B$14)+1) - $K$4 + 1)>$K$5,"",(($I14*7 + COLUMN()-COLUMN($B$14)+1) - $K$4 + 1))) | I14: 5
B15: =IF(B14="","",IFERROR(VLOOKUP(TEXT(DATE(CONFIG!$B$1,$K$2,B14),"mm-dd"),LECTURAS!$A$2:$B$1000,2,FALSE),"")) | C15: =IF(C14="","",IFERROR(VLOOKUP(TEXT(DATE(CONFIG!$B$1,$K$2,C14),"mm-dd"),LECTURAS!$A$2:$B$1000,2,FALSE),"")) | D15: =IF(D14="","",IFERROR(VLOOKUP(TEXT(DATE(CONFIG!$B$1,$K$2,D14),"mm-dd"),LECTURAS!$A$2:$B$1000,2,FALSE),"")) | E15: =IF(E14="","",IFERROR(VLOOKUP(TEXT(DATE(CONFIG!$B$1,$K$2,E14),"mm-dd"),LECTURAS!$A$2:$B$1000,2,FALSE),"")) | F15: =IF(F14="","",IFERROR(VLOOKUP(TEXT(DATE(CONFIG!$B$1,$K$2,F14),"mm-dd"),LECTURAS!$A$2:$B$1000,2,FALSE),"")) | G15: =IF(G14="","",IFERROR(VLOOKUP(TEXT(DATE(CONFIG!$B$1,$K$2,G14),"mm-dd"),LECTURAS!$A$2:$B$1000,2,FALSE),"")) | H15: =IF(H14="","",IFERROR(VLOOKUP(TEXT(DATE(CONFIG!$B$1,$K$2,H14),"mm-dd"),LECTURAS!$A$2:$B$1000,2,FALSE),"")) | I15: 5

Sheet Mayo
A1: Mayo | J1: 5
A2: Domingo | B2: Lunes | C2: Martes | D2: Miércoles | E2: Jueves | F2: Viernes | G2: Sábado | J2: =DATE(CONFIG!$B$1,$J$1,1) -> 46143
A3: =IF((($H3*7 + COLUMN()-COLUMN($A$3)+1) - $J$3 + 1)<1,"",IF((($H3*7 + COLUMN()-COLUMN($A$3)+1) - $J$3 + 1)>$J$4,"",(($H3*7 + COLUMN()-COLUMN($A$3)+1) - $J$3 + 1))) | B3: =IF((($H3*7 + COLUMN()-COLUMN($A$3)+1) - $J$3 + 1)<1,"",IF((($H3*7 + COLUMN()-COLUMN($A$3)+1) - $J$3 + 1)>$J$4,"",(($H3*7 + COLUMN()-COLUMN($A$3)+1) - $J$3 + 1))) | C3: =IF((($H3*7 + COLUMN()-COLUMN($A$3)+1) - $J$3 + 1)<1,"",IF((($H3*7 + COLUMN()-COLUMN($A$3)+1) - $J$3 + 1)>$J$4,"",(($H3*7 + COLUMN()-COLUMN($A$3)+1) - $J$3 + 1))) | D3: =IF((($H3*7 + COLUMN()-COLUMN($A$3)+1) - $J$3 + 1)<1,"",IF((($H3*7 + COLUMN()-COLUMN($A$3)+1) - $J$3 + 1)>$J$4,"",(($H3*7 + COLUMN()-COLUMN($A$3)+1) - $J$3 + 1))) | E3: =IF((($H3*7 + COLUMN()-COLUMN($A$3)+1) - $J$3 + 1)<1,"",IF((($H3*7 + COLUMN()-COLUMN($A$3)+1) - $J$3 + 1)>$J$4,"",(($H3*7 + COLUMN()-COLUMN($A$3)+1) - $J$3 + 1))) | F3: =IF((($H3*7 + COLUMN()-COLUMN($A$3)+1) - $J$3 + 1)<1,"",IF((($H3*7 + COLUMN()-COLUMN($A$3)+1) - $J$3 + 1)>$J$4,"",(($H3*7 + COLUMN()-COLUMN($A$3)+1) - $J$3 + 1))) -> 1 | G3: =IF((($H3*7 + COLUMN()-COLUMN($A$3)+1) - $J$3 + 1)<1,"",IF((($H3*7 + COLUMN()-COLUMN($A$3)+1) - $J$3 + 1)>$J$4,"",(($H3*7 + COLUMN()-COLUMN($A$3)+1) - $J$3 + 1))) -> 2 | H3: 0 | J3: =WEEKDAY($J$2,1) -> 6
A4: =IF(A3="","",IFERROR(VLOOKUP(TEXT(DATE(CONFIG!$B$1,$J$1,A3),"mm-dd"),LECTURAS!$A$2:$B$1000,2,FALSE),"")) | B4: =IF(B3="","",IFERROR(VLOOKUP(TEXT(DATE(CONFIG!$B$1,$J$1,B3),"mm-dd"),LECTURAS!$A$2:$B$1000,2,FALSE),"")) | C4: =IF(C3="","",IFERROR(VLOOKUP(TEXT(DATE(CONFIG!$B$1,$J$1,C3),"mm-dd"),LECTURAS!$A$2:$B$1000,2,FALSE),"")) | D4: =IF(D3="","",IFERROR(VLOOKUP(TEXT(DATE(CONFIG!$B$1,$J$1,D3),"mm-dd"),LECTURAS!$A$2:$B$1000,2,FALSE),"")) | E4: =IF(E3="","",IFERROR(VLOOKUP(TEXT(DATE(CONFIG!$B$1,$J$1,E3),"mm-dd"),LECTURAS!$A$2:$B$1000,2,FALSE),"")) | F4: =IF(F3="","",IFERROR(VLOOKUP(TEXT(DATE(CONFIG!$B$1,$J$1,F3),"mm-dd"),LECTURAS!$A$2:$B$1000,2,FALSE),"")) -> 1 Samuel 18–19; Salmo 10 | G4: =IF(G3="","",IFERROR(VLOOKUP(TEXT(DATE(CONFIG!$B$1,$J$1,G3),"mm-dd"),LECTURAS!$A$2:$B$1000,2,FALSE),"")) -> 1 Samuel 20–21; Salmo 11 | H4: 0 | J4: =DAY(EOMONTH($J$2,0)) -> 31
A5: =IF((($H5*7 + COLUMN()-COLUMN($A$5)+1) - $J$3 + 1)<1,"",IF((($H5*7 + COLUMN()-COLUMN($A$5)+1) - $J$3 + 1)>$J$4,"",(($H5*7 + COLUMN()-COLUMN($A$5)+1) - $J$3 + 1))) -> 3 | B5: =IF((($H5*7 + COLUMN()-COLUMN($A$5)+1) - $J$3 + 1)<1,"",IF((($H5*7 + COLUMN()-COLUMN($A$5)+1) - $J$3 + 1)>$J$4,"",(($H5*7 + COLUMN()-COLUMN($A$5)+1) - $J$3 + 1))) -> 4 | C5: =IF((($H5*7 + COLUMN()-COLUMN($A$5)+1) - $J$3 + 1)<1,"",IF((($H5*7 + COLUMN()-COLUMN($A$5)+1) - $J$3 + 1)>$J$4,"",(($H5*7 + COLUMN()-COLUMN($A$5)+1) - $J$3 + 1))) -> 5 | D5: =IF((($H5*7 + COLUMN()-COLUMN($A$5)+1) - $J$3 + 1)<1,"",IF((($H5*7 + COLUMN()-COLUMN($A$5)+1) - $J$3 + 1)>$J$4,"",(($H5*7 + COLUMN()-COLUMN($A$5)+1) - $J$3 + 1))) -> 6 | E5: =IF((($H5*7 + COLUMN()-COLUMN($A$5)+1) - $J$3 + 1)<1,"",IF((($H5*7 + COLUMN()-COLUMN($A$5)+1) - $J$3 + 1)>$J$4,"",(($H5*7 + COLUMN()-COLUMN($A$5)+1) - $J$3 + 1))) -> 7 | F5: =IF((($H5*7 + COLUMN()-COLUMN($A$5)+1) - $J$3 + 1)<1,"",IF((($H5*7 + COLUMN()-COLUMN($A$5)+1) - $J$3 + 1)>$J$4,"",(($H5*7 + COLUMN()-COLUMN($A$5)+1) - $J$3 + 1))) -> 8 | G5: =IF((($H5*7 + COLUMN()-COLUMN($A$5)+1) - $J$3 + 1)<1,"",IF((($H5*7 + COLUMN()-COLUMN($A$5)+1) - $J$3 + 1)>$J$4,"",(($H5*7 + COLUMN()-COLUMN($A$5)+1) - $J$3 + 1))) -> 9 | H5: 1
A6: =IF(A5="","",IFERROR(VLOOKUP(TEXT(DATE(CONFIG!$B$1,$J$1,A5),"mm-dd"),LECTURAS!$A$2:$B$1000,2,FALSE),"")) -> 1 Samuel 22–23; Salmo 12 | B6: =IF(B5="","",IFERROR(VLOOKUP(TEXT(DATE(CONFIG!$B$1,$J$1,B5),"mm-dd"),LECTURAS!$A$2:$B$1000,2,FALSE),"")) -> 1 Samuel 24–25; Salmo 13 | C6: =IF(C5="","",IFERROR(VLOOKUP(TEXT(DATE(CONFIG!$B$1,$J$1,C5),"mm-dd"),LECTURAS!$A$2:$B$1000,2,FALSE),"")) -> 1 Samuel 26–27; Salmo 14 | D6: =IF(D5="","",IFERROR(VLOOKUP(TEXT(DATE(CONFIG!$B$1,$J$1,D5),"mm-dd"),LECTURAS!$A$2:$B$1000,2,FALSE),"")) -> 1 Samuel 28–31 | E6: =IF(E5="","",IFERROR(VLOOKUP(TEXT(DATE(CONFIG!$B$1,$J$1,E5),"mm-dd"),LECTURAS!$A$2:$B$1000,2,FALSE),"")) -> 2 Samuel 1–2; Salmo 15–17 | F6: =IF(F5="","",IFERROR(VLOOKUP(TEXT(DATE(CONFIG!$B$1,$J$1,F5),"mm-dd"),LECTURAS!$A$2:$B$1000,2,FALSE),"")) -> 2 Samuel 3–4; Salmo 18 | G6: =IF(G5="","",IFERROR(VLOOKUP(TEXT(DATE(CONFIG!$B$1,$J$1,G5),"mm-dd"),LECTURAS!$A$2:$B$1000,2,FALSE),"")) -> 2 Samuel 5–6; Salmo 19 | H6: 1
